Workbook

Sheet inputs
A1: parameter | B1: value | C1: notes
A2: long_haul_threshold | B2: 600 | C2: Distance threshold to consider long-haul trucking (km). 2x operating radius of 300km in Sebastian's work
A3: autonomie_tech_case | B3: Low | C3: Autonomie technological progress ('Case')
A4: overnight_charging_share | B4: 0.5 | C4: Share of overnight charging vs. (overnight + fast) charging. Placeholder value. To be updated from truck charging simulator using GPS data
A5: eRoads_max_aadtt | B5: 42000 | C5: - Large trucks have speed limit cap of 105 km/h, following distance at least 60 metres (https://www.ontario.ca/document/official-ministry-transportation-mto-truck-handbook/driver-conduct) - Truck headway: (60m / (105km/h * 1000 / 3600)) = 2.057 seconds - Maximum truck flow per day = (60sec * 60min * 24hr) / 2.057sec = 42,000 trucks/day

Sheet truck_specs
A1: tech_veh | B1: tech_supply | C1: Bin | D1: Powertrain | E1: desired_range_km | F1: eRoads_equipment_kg | G1: eRoads_equipment_cost | H1: charger_standard_kW | I1: charger_fast_kW | J1: avg_capacity_factor | K1: notes
A2: T_HDV_T_LH_BEV_LRGBATT | B2: T_HDV_T_LH_CHRG_LRGBATT | C2: NaN | D2: BEV | E2: =1.5*500*1.609 -> 1206.75 | F2: 0 | G2: 0 | H2: 350 | I2: 350 | J2: 0.2 | K2: desired range: 1.5x of Autonomie range (500 miles). Enough for 12h constant driving at 100 km/h. avg_capacity_factor: Travel Center. Long-term utilization. (Bennett 2022)
A3: T_HDV_T_LH_BEV_FSTCHRG | B3: T_HDV_T_LH_CHRG_FSTCHRG | C3: NaN | D3: BEV | E3: =500*1.609 -> 804.5 | F3: 0 | G3: 0 | H3: 350 | I3: 3000 | J3: 0.08 | K3: desired range: same as Autonomie range (500 miles). Megawatt charging system max power 3MW (Bennett 2022) avg_capacity_factor: En Route, 3 MW charger. Long-term utilization. Average of low and high utilization (Bennett 2022)
A4: T_HDV_T_LH_BEV_ERDS1 | B4: T_HDV_T_LH_CHRG_ERDS1 | C4: 1 | D4: BEV | E4: =0.5*500*1.609 -> 402.25 | F4: 100 | G4: 7500 | H4: NaN | I4: NaN | J4: ='MTO iCorridor AADTT'!$AA9/inputs!$B$5 -> 0.37689159 | K4: desired range: 0.5x of Autonomie range (500 miles). eRoads onboard equipment weight: 100 kg (Yeow et al 2024), cost: 2020 US$7,500 (Yeow et al 2024)
A5: T_HDV_T_LH_BEV_ERDS2 | B5: T_HDV_T_LH_CHRG_ERDS2 | C5: 2 | D5: BEV | E5: =0.5*500*1.609 -> 402.25 | F5: 100 | G5: 7500 | H5: NaN | I5: NaN | J5: ='MTO iCorridor AADTT'!$AA10/inputs!$B$5 -> 0.13977148 | K5: desired range: 0.5x of Autonomie range (500 miles). eRoads onboard equipment weight: 100 kg (Yeow et al 2024), cost: 2020 US$7,500 (Yeow et al 2024)
A6: T_HDV_T_LH_BEV_ERDS3 | B6: T_HDV_T_LH_CHRG_ERDS3 | C6: 3 | D6: BEV | E6: =0.5*500*1.609 -> 402.25 | F6: 100 | G6: 7500 | H6: NaN | I6: NaN | J6: ='MTO iCorridor AADTT'!$AA11/inputs!$B$5 -> 0.037129023 | K6: desired range: 0.5x of Autonomie range (500 miles). eRoads onboard equipment weight: 100 kg (Yeow et al 2024), cost: 2020 US$7,500 (Yeow et al 2024)
A7: T_HDV_T_LH_BEV_ERDS4 | B7: T_HDV_T_LH_CHRG_ERDS4 | C7: 4 | D7: BEV | E7: =0.5*500*1.609 -> 402.25 | F7: 100 | G7: 7500 | H7: NaN | I7: NaN | J7: ='MTO iCorridor AADTT'!$AA12/inputs!$B$5 -> 0.01414131 | K7: desired range: 0.5x of Autonomie range (500 miles). eRoads onboard equipment weight: 100 kg (Yeow et al 2024), cost: 2020 US$7,500 (Yeow et al 2024)
A8: T_HDV_T_LH_BEV_ERDS5 | B8: T_HDV_T_LH_CHRG_ERDS5 | C8: 5 | D8: BEV | E8: =0.5*500*1.609 -> 402.25 | F8: 100 | G8: 7500 | H8: NaN | I8: NaN | J8: ='MTO iCorridor AADTT'!$AA13/inputs!$B$5 -> 0.0020924996 | K8: desired range: 0.5x of Autonomie range (500 miles). eRoads onboard equipment weight: 100 kg (Yeow et al 2024), cost: 2020 US$7,500 (Yeow et al 2024)
A9: T_HDV_T_LH_FCEV | B9: T_H2_HDV_T_LH_REFUEL | C9: NaN | D9: FCEV | E9: =500*1.609 -> 804.5 | F9: 0 | G9: 0 | H9: =13.2*120*1000/60 -> 26400 | I9: =H9 -> 26400 | J9: 0.5 | K9: desired range: same as Autonomie range (500 miles). Fill rate: Demonstrated 13.2 kgH2/min average (https://www.nrel.gov/news/detail/program/2022/fast-flow-future-heavy-duty-hydrogen-trucks). LHV 120MJ/kgH2. avg_capacity_factor: 50% from IEA Future of Hydrogen Report Assumptions Annex - Distribution https://iea.blob.core.windows.net/assets/29b027e5-fefc-47df-aed0-456b1bb38844/IEA-The-Future-of-Hydrogen-Assumptions-Annex_CORR.pdf

Sheet database_index
A1: db_id | B1: db_path | C1: db_path_old | D1: profile_name | E1: display_name | F1: db_date | G1: num_rep_days | H1: temoa_version | I1: notes
A2: aaa | B2: =_xlfn.CONCAT(A2, ".sqlite") -> aaa.sqlite | C2: canoe_on_16d_baseline_newtech_v3_1 | E2: Baseline new tech | F2: 20260101 | G2: 16 | H2: 3_1 | I2: Baseline, root database
A3: wrn | B3: =_xlfn.CONCAT(A3, ".sqlite") -> wrn.sqlite | C3: canoe_on_16d_baseline_newtech_atriprofiles_v3_1 | D3: Min power | E3: ATRI data min power | F3: 20260101 | G3: 16 | H3: 3_1
A4: ljv | B4: =_xlfn.CONCAT(A4, ".sqlite") -> ljv.sqlite | C4: canoe_on_16d_baseline_newtech_flat_v3_1 | D4: Flat | E4: Flat | F4: 20260101 | G4: 16 | H4: 3_1
A5: rhl | B5: =_xlfn.CONCAT(A5, ".sqlite") -> rhl.sqlite | C5: canoe_on_16d_baseline_newtech_simplemiddaypeak_v3_1 | D5: Simple mid-day peak | E5: Simple mid-day peak | F5: 20260101 | G5: 16 | H5: 3_1
A6: mid | B6: =_xlfn.CONCAT(A6, ".sqlite") -> mid.sqlite | C6: canoe_on_16d_baseline_newtech_nolhhdtelec_v3_1 | D6: nolhhdtelec | E6: No long-haul HDT electrification | F6: 20260101 | G6: 16 | H6: 3_1
A7: nhh | B7: =_xlfn.CONCAT(A7, ".sqlite") -> nhh.sqlite | C7: canoe_on_16d_baseline_newtech_flexdemand_v3_1 | D7: Flexible | E7: Flexible | F7: 20260101 | G7: 16 | H7: 3_1
A8: soe | B8: =_xlfn.CONCAT(A8, ".sqlite") -> soe.sqlite | C8: canoe_on_16d_baseline_newtech_atriprofiles_H2DACeDiesel_v3_1 | D8: ATRI data, min power | E8: Forcing H2 and e-diesel | F8: 20260101 | G8: 16 | H8: 3_1 | I8: - Long-haul trucks can only be diesel and H2FCETs (no BEVs) - Only allow H2 produced with PEM - Gradually phase out petroleum diesel
A9: cqh | B9: =_xlfn.CONCAT(A9, ".sqlite") -> cqh.sqlite | C9: canoe_on_16d_baseline_newtech_solarfreeflip_v3_1 | D9: freesolar flippedpeak | E9: Free solar flipped peak | F9: 20260101 | G9: 16 | H9: 3_1
A10: xcc | B10: =_xlfn.CONCAT(A10, ".sqlite") -> xcc.sqlite | C10: canoe_on_16d_baseline_newtech_todtest_v3_1 | E10: Time of day test | F10: 20260101 | G10: 16 | H10: 3_1
A11: iyw | B11: =_xlfn.CONCAT(A11, ".sqlite") -> iyw.sqlite | D11: Immediate | E11: ATRI data immediate | F11: 20260101 | G11: 16 | H11: 3_1
A12: jmo | B12: =_xlfn.CONCAT(A12, ".sqlite") -> jmo.sqlite | D12: Delayed | E12: ATRI data delayed | F12: 20260101 | G12: 16 | H12: 3_1
A13: fnh | B13: =_xlfn.CONCAT(A13, ".sqlite") -> fnh.sqlite | D13: ATRI data, min power | E13: Forcing H2 and e-diesel no solar wind D204 | F13: 20260101 | G13: 16 | H13: 3_1
A14: gkl | B14: =_xlfn.CONCAT(A14, ".sqlite") -> gkl.sqlite | D14: ATRI data, min power | E14: ATRI data min power swapped seasons VRE LHHDT | F14: 20260101 | G14: 16 | H14: 3_1
A15: hwj | B15: =_xlfn.CONCAT(A15, ".sqlite") -> hwj.sqlite | C15: canoe_dataset_ON_16d_bevsplit_growthlim_H2 | D15: Original CANOE national database | E15: Original CANOE national database | F15: 20260507 | G15: 16 | H15: 3_1 | I15: Started with original/canoe_dataset.sqlite; CANOE national database received from Dijuan on 2026 May 11. Originally from Davey on 2026 May 07; After CANOE_interface (ON, high res all sectors, current measures); After time series clustering (representative_periods) to get 16 days; After adding Dijuan's LDV BEV sales share mix, growth rate constraints. After adding H2 production, distribution and compression
A16: uez | B16: =_xlfn.CONCAT(A16, ".sqlite") -> uez.sqlite | D16: nolhhdtelec | E16: No long-haul HDT electrification | F16: 20260507 | G16: 16 | H16: 3_1
A17: htl | B17: =_xlfn.CONCAT(A17, ".sqlite") -> htl.sqlite | D17: Flexible | E17: Flexible | F17: 20260507 | G17: 16 | H17: 3_1
A18: aum | B18: =_xlfn.CONCAT(A18, ".sqlite") -> aum.sqlite | D18: Min power | E18: ATRI data min power | F18: 20260507 | G18: 16 | H18: 3_1
A19: xlv | B19: =_xlfn.CONCAT(A19, ".sqlite") -> xlv.sqlite | D19: Immediate | E19: ATRI data immediate | F19: 20260507 | G19: 16 | H19: 3_1
A20: bxl | B20: =_xlfn.CONCAT(A20, ".sqlite") -> bxl.sqlite | D20: Delayed | E20: ATRI data delayed | F20: 20260507 | G20: 16 | H20: 3_1
A21: roa | B21: =_xlfn.CONCAT(A21, ".sqlite") -> roa.sqlite | D21: Flat | E21: Flat | F21: 20260507 | G21: 16 | H21: 3_1
A22: xuw | B22: =_xlfn.CONCAT(A22, ".sqlite") -> xuw.sqlite | D22: Simple mid-day peak | E22: Simple mid-day peak | F22: 20260507 | G22: 16 | H22: 3_1
A23: myh | B23: =_xlfn.CONCAT(A23, ".sqlite") -> myh.sqlite | D23: ATRI data, min power | E23: Forcing H2 and e-diesel | F23: 20260507 | G23: 16 | H23: 3_1 | I23: - Long-haul trucks can only be diesel and H2FCETs (no BEVs) - Only allow H2 produced with PEM - Gradually phase out petroleum diesel
A24: nzx | B24: =_xlfn.CONCAT(A24, ".sqlite") -> nzx.sqlite | C24: ON_16d_bevsplit_growthlim_newtech | D24: Baseline new tech | E24: Baseline new tech | F24: 20260507 | G24: 16 | H24: 3_1 | I24: With social cost of carbon, long-haul truck disaggregation
A25: wtz | B25: =_xlfn.CONCAT(A25, ".sqlite") -> wtz.sqlite | D25: Immediate, fuel cost | E25: ATRI data immediate fuel cost | F25: 20260507 | G25: 16 | H25: 3_1 | I25: With dummy bypass techs to estimate equivalent fuel costs
A26: izo | B26: =_xlfn.CONCAT(A26, ".sqlite") -> izo.sqlite | D26: Immediate, fuel cost, no ediesel | E26: ATRI data immediate fuel cost no ediesel | F26: 20260507 | G26: 16 | H26: 3_1 | I26: With dummy bypass techs to estimate equivalent fuel costs, no e-diesel
A27: xnc | B27: =_xlfn.CONCAT(A27, ".sqlite") -> xnc.sqlite | D27: Immediate, fuel cost, no eroads | E27: ATRI data immediate fuel cost no eroads | F27: 20260507 | G27: 16 | H27: 3_1 | I27: With dummy bypass techs to estimate equivalent fuel costs, no eroads
A28: lii | B28: =_xlfn.CONCAT(A28, ".sqlite") -> lii.sqlite | D28: Immediate, upstream cost | E28: ATRI data immediate upstream cost | F28: 20260507 | G28: 16 | H28: 3_1 | I28: With dummy techs to estimate upstream costs
A29: kki | B29: =_xlfn.CONCAT(A29, ".sqlite") -> kki.sqlite | D29: Flat, upstream cost | E29: Flat upstream cost | F29: 20260507 | G29: 16 | H29: 3_1 | I29: With dummy techs to estimate upstream costs
A30: oqh | B30: =_xlfn.CONCAT(A30, ".sqlite") -> oqh.sqlite | D30: Immediate, duals | E30: Immediate duals | F30: 20260507 | G30: 16 | H30: 3_1 | I30: With transfer techs to observe duals
A31: olr | B31: =_xlfn.CONCAT(A31, ".sqlite") -> olr.sqlite
A32: uoj | B32: =_xlfn.CONCAT(A32, ".sqlite") -> uoj.sqlite
A33: oog | B33: =_xlfn.CONCAT(A33, ".sqlite") -> oog.sqlite
A34: esf | B34: =_xlfn.CONCAT(A34, ".sqlite") -> esf.sqlite
A35: qjw | B35: =_xlfn.CONCAT(A35, ".sqlite") -> qjw.sqlite
A36: rix | B36: =_xlfn.CONCAT(A36, ".sqlite") -> rix.sqlite
A37: glw | B37: =_xlfn.CONCAT(A37, ".sqlite") -> glw.sqlite
A38: vth | B38: =_xlfn.CONCAT(A38, ".sqlite") -> vth.sqlite
A39: sbb | B39: =_xlfn.CONCAT(A39, ".sqlite") -> sbb.sqlite
A40: qdd | B40: =_xlfn.CONCAT(A40, ".sqlite") -> qdd.sqlite
...

Sheet sample_profiles
A1: tod | B1: flat | C1: simple_midday_peak
A2: H01 | B2: 1 | C2: =ROUND(SIN(PI()*(ROW(C2)-2)/23)^2, 3) -> 0
A3: H02 | B3: 1 | C3: =ROUND(SIN(PI()*(ROW(C3)-2)/23)^2, 3) -> 0.019
A4: H03 | B4: 1 | C4: =ROUND(SIN(PI()*(ROW(C4)-2)/23)^2, 3) -> 0.073
A5: H04 | B5: 1 | C5: =ROUND(SIN(PI()*(ROW(C5)-2)/23)^2, 3) -> 0.159
A6: H05 | B6: 1 | C6: =ROUND(SIN(PI()*(ROW(C6)-2)/23)^2, 3) -> 0.27
A7: H06 | B7: 1 | C7: =ROUND(SIN(PI()*(ROW(C7)-2)/23)^2, 3) -> 0.398
A8: H07 | B8: 1 | C8: =ROUND(SIN(PI()*(ROW(C8)-2)/23)^2, 3) -> 0.534
A9: H08 | B9: 1 | C9: =ROUND(SIN(PI()*(ROW(C9)-2)/23)^2, 3) -> 0.667
A10: H09 | B10: 1 | C10: =ROUND(SIN(PI()*(ROW(C10)-2)/23)^2, 3) -> 0.788
A11: H10 | B11: 1 | C11: =ROUND(SIN(PI()*(ROW(C11)-2)/23)^2, 3) -> 0.888
A12: H11 | B12: 1 | C12: =ROUND(SIN(PI()*(ROW(C12)-2)/23)^2, 3) -> 0.959
A13: H12 | B13: 1 | C13: =ROUND(SIN(PI()*(ROW(C13)-2)/23)^2, 3) -> 0.995
... A25: H24 | B25: 1 | C25: =ROUND(SIN(PI()*(ROW(C25)-2)/23)^2, 3) -> 0

Sheet MTO iCorridor AADTT
A1: FID | B1: FID_1 | C1: ID | D1: LENGTH | E1: LHRS | F1: OFFSET | G1: TRAFFICSEC | H1: HIGHWAY | I1: AADTT19 | J1: AADTT19xLength | K1: AADTT19_rank | L1: AADTT19_cumsum | M1: AADTT19xLength_cumsum | N1: LENGTH_cumsum | O1: LENGTH_cumsum_prop | P1: Bin
A2: 66 | B2: 862 | C2: 1618 | D2: 2.14 | E2: 47673 | F2: 0 | G2: 47673000 | H2: 401 | I2: 46100 | J2: =I2*D2 -> 98654 | K2: 1 | L2: =SUM($I$2:$I2) -> 46100 | M2: =SUM($J$2:$J2) -> 98654 | N2: =SUM($D$2:$D2) -> 2.14 | O2: =N2/$T$4 -> 0.00012752989 | P2: {=SUMPRODUCT((O2>$T$9:$T$14)*(O2<=$U$9:$U$14),$S$9:$S$14)} -> 1
A3: 905 | B3: 531 | C3: 171 | D3: 1.01 | E3: 10116 | F3: 0 | G3: 10116000 | H3: QEW | I3: 45900 | J3: =I3*D3 -> 46359 | K3: 2 | L3: =SUM($I$2:$I3) -> 92000 | M3: =SUM($J$2:$J3) -> 145013 | N3: =SUM($D$2:$D3) -> 3.15 | O3: =N3/$T$4 -> 0.00018771923 | P3: {=SUMPRODUCT((O3>$T$9:$T$14)*(O3<=$U$9:$U$14),$S$9:$S$14)} -> 1 | R3: AADTT19_sum | S3: AADTT19xLength_sum | T3: LENGTH_sum
A4: 1549 | B4: 381 | C4: 1525 | D4: 4.59 | E4: 47730 | F4: 0 | G4: 47730000 | H4: 401 | I4: 45000 | J4: =I4*D4 -> 206550 | K4: 3 | L4: =SUM($I$2:$I4) -> 137000 | M4: =SUM($J$2:$J4) -> 351563 | N4: =SUM($D$2:$D4) -> 7.74 | O4: =N4/$T$4 -> 0.00046125296 | P4: {=SUMPRODUCT((O4>$T$9:$T$14)*(O4<=$U$9:$U$14),$S$9:$S$14)} -> 1 | R4: =SUM($I$2:$I$1845) -> 6345680 | S4: =SUM($J$2:$J$1845) -> 25360717 | T4: =SUM(D2:D1854) -> 16780.38
A5: 904 | B5: 530 | C5: 170 | D5: 0.81 | E5: 10120 | F5: 0 | G5: 10120000 | H5: QEW | I5: 42900 | J5: =I5*D5 -> 34749 | K5: 4 | L5: =SUM($I$2:$I5) -> 179900 | M5: =SUM($J$2:$J5) -> 386312 | N5: =SUM($D$2:$D5) -> 8.55 | O5: =N5/$T$4 -> 0.00050952362 | P5: {=SUMPRODUCT((O5>$T$9:$T$14)*(O5<=$U$9:$U$14),$S$9:$S$14)} -> 1
A6: 903 | B6: 529 | C6: 168 | D6: 1.92 | E6: 10121 | F6: 0 | G6: 10121000 | H6: QEW | I6: 42400 | J6: =I6*D6 -> 81408 | K6: 5 | L6: =SUM($I$2:$I6) -> 222300 | M6: =SUM($J$2:$J6) -> 467720 | N6: =SUM($D$2:$D6) -> 10.47 | O6: =N6/$T$4 -> 0.00062394296 | P6: {=SUMPRODUCT((O6>$T$9:$T$14)*(O6<=$U$9:$U$14),$S$9:$S$14)} -> 1
A7: 1627 | B7: 1627 | C7: 2120 | D7: 1.45 | E7: 47660 | F7: 0 | G7: 47660000 | H7: 401 | I7: 42100 | J7: =I7*D7 -> 61045 | K7: 6 | L7: =SUM($I$2:$I7) -> 264400 | M7: =SUM($J$2:$J7) -> 528765 | N7: =SUM($D$2:$D7) -> 11.92 | O7: =N7/$T$4 -> 0.0007103534 | P7: {=SUMPRODUCT((O7>$T$9:$T$14)*(O7<=$U$9:$U$14),$S$9:$S$14)} -> 1 | R7: Custom bin length
A8: 377 | B8: 1172 | C8: 2056 | D8: 1.41 | E8: 47661 | F8: 0 | G8: 47661000 | H8: 401 | I8: 41800 | J8: =I8*D8 -> 58938 | K8: 7 | L8: =SUM($I$2:$I8) -> 306200 | M8: =SUM($J$2:$J8) -> 587703 | N8: =SUM($D$2:$D8) -> 13.33 | O8: =N8/$T$4 -> 0.0007943801 | P8: {=SUMPRODUCT((O8>$T$9:$T$14)*(O8<=$U$9:$U$14),$S$9:$S$14)} -> 1 | R8: Top xx% | S8: Bin | T8: start % | U8: end % | V8: Cumulative length (km) | W8: Length (km) | X8: AADTT19_cumsum | Y8: cumul perc of AADTT19 | Z8: perc of AADTT19 | AA8: Length wt avg AADTT19 | AB8: LenWtAvgAADTT19 X PercAADTT19 | AD8: LenWtAvgAADTT 19 X Length | AE8: % of total
A9: 85 | B9: 881 | C9: 1638 | D9: 0.76 | E9: 47671 | F9: 0 | G9: 47671000 | H9: 401 | I9: 40500 | J9: =I9*D9 -> 30780 | K9: 8 | L9: =SUM($I$2:$I9) -> 346700 | M9: =SUM($J$2:$J9) -> 618483 | N9: =SUM($D$2:$D9) -> 14.09 | O9: =N9/$T$4 -> 0.00083967109 | P9: {=SUMPRODUCT((O9>$T$9:$T$14)*(O9<=$U$9:$U$14),$S$9:$S$14)} -> 1 | R9: 0.05 | S9: 1 | T9: 0 | U9: =R9 -> 0.05 | V9: =(R9-0)*$T$4 -> 839.019 | W9: =R9*$T$4 -> 839.019 | X9: =SUMIF($N$2:$N$1845,"<="&$V9,$I$2:$I$1845) -> 4344750 | Y9: =X9/$R$4 -> 0.6846784 | Z9: =Y9 -> 0.6846784 | AA9: =SUMIF($P$2:$P$1845,$S9,$J$2:$J$1845)/W9 -> 15829.447 | AB9: =AA9*Y9 -> 10838.08 | AD9: =AA9*W9 -> 13281206 | AE9: =AD9/SUM($AD$9:$AD$14) -> 0.52369206
A10: 1610 | B10: 1610 | C10: 2100 | D10: 2.48 | E10: 47663 | F10: 0 | G10: 47663000 | H10: 401 | I10: 40300 | J10: =I10*D10 -> 99944 | K10: 9 | L10: =SUM($I$2:$I10) -> 387000 | M10: =SUM($J$2:$J10) -> 718427 | N10: =SUM($D$2:$D10) -> 16.57 | O10: =N10/$T$4 -> 0.00098746274 | P10: {=SUMPRODUCT((O10>$T$9:$T$14)*(O10<=$U$9:$U$14),$S$9:$S$14)} -> 1 | R10: 0.1 | S10: 2 | T10: =R9 -> 0.05 | U10: =R10 -> 0.1 | V10: =(R10-0)*$T$4 -> 1678.038 | W10: =(R10-R9)*$T$4 -> 839.019 | X10: =SUMIF($N$2:$N$1845,"<="&$V10,$I$2:$I$1845) -> 5379750 | Y10: =X10/$R$4 -> 0.84778148 | Z10: =Y10-Y9 -> 0.16310309 | AA10: =SUMIF($P$2:$P$1845,$S10,$J$2:$J$1845)/W10 -> 5870.4022 | AB10: =AA10*Y10 -> 4976.8183 | AD10: =AA10*W10 -> 4925379 | AE10: =AD10/SUM($AD$9:$AD$14) -> 0.19421292
A11: 36 | B11: 832 | C11: 1586 | D11: 4.36 | E11: 47672 | F11: 0 | G11: 47672000 | H11: 401 | I11: 37200 | J11: =I11*D11 -> 162192 | K11: 10 | L11: =SUM($I$2:$I11) -> 424200 | M11: =SUM($J$2:$J11) -> 880619 | N11: =SUM($D$2:$D11) -> 20.93 | O11: =N11/$T$4 -> 0.00124729 | P11: {=SUMPRODUCT((O11>$T$9:$T$14)*(O11<=$U$9:$U$14),$S$9:$S$14)} -> 1 | R11: 0.25 | S11: 3 | T11: =R10 -> 0.1 | U11: =R11 -> 0.25 | V11: =(R11-0)*$T$4 -> 4195.095 | W11: =(R11-R10)*$T$4 -> 2517.057 | X11: =SUMIF($N$2:$N$1845,"<="&$V11,$I$2:$I$1845) -> 6019990 | Y11: =X11/$R$4 -> 0.94867532 | Z11: =Y11-Y10 -> 0.10089384 | AA11: =SUMIF($P$2:$P$1845,$S11,$J$2:$J$1845)/W11 -> 1559.419 | AB11: =AA11*Y11 -> 1479.3823 | AD11: =AA11*W11 -> 3925146.4 | AE11: =AD11/SUM($AD$9:$AD$14) -> 0.15477269
A12: 86 | B12: 882 | C12: 1639 | D12: 2.8 | E12: 48250 | F12: 0 | G12: 48250000 | H12: 403 | I12: 35400 | J12: =I12*D12 -> 99120 | K12: 11 | L12: =SUM($I$2:$I12) -> 459600 | M12: =SUM($J$2:$J12) -> 979739 | N12: =SUM($D$2:$D12) -> 23.73 | O12: =N12/$T$4 -> 0.0014141515 | P12: {=SUMPRODUCT((O12>$T$9:$T$14)*(O12<=$U$9:$U$14),$S$9:$S$14)} -> 1 | R12: 0.5 | S12: 4 | T12: =R11 -> 0.25 | U12: =R12 -> 0.5 | V12: =(R12-0)*$T$4 -> 8390.19 | W12: =(R12-R11)*$T$4 -> 4195.095 | X12: =SUMIF($N$2:$N$1845,"<="&$V12,$I$2:$I$1845) -> 6296010 | Y12: =X12/$R$4 -> 0.99217263 | Z12: =Y12-Y11 -> 0.043497308 | AA12: =SUMIF($P$2:$P$1845,$S12,$J$2:$J$1845)/W12 -> 593.93504 | AB12: =AA12*Y12 -> 589.28609 | AD12: =AA12*W12 -> 2491613.9 | AE12: =AD12/SUM($AD$9:$AD$14) -> 0.09824698
A13: 16 | B13: 812 | C13: 1563 | D13: 2.74 | E13: 48255 | F13: 0 | G13: 48255000 | H13: 403 | I13: 35000 | J13: =I13*D13 -> 95900 | K13: 12 | L13: =SUM($I$2:$I13) -> 494600 | M13: =SUM($J$2:$J13) -> 1075639 | N13: =SUM($D$2:$D13) -> 26.47 | O13: =N13/$T$4 -> 0.0015774375 | P13: {=SUMPRODUCT((O13>$T$9:$T$14)*(O13<=$U$9:$U$14),$S$9:$S$14)} -> 1 | R13: 1 | S13: 5 | T13: =R12 -> 0.5 | U13: =R13 -> 1 | V13: =(R13-0)*$T$4 -> 16780.38 | W13: =(R13-R12)*$T$4 -> 8390.19 | X13: =SUMIF($N$2:$N$1845,"<="&$V13,$I$2:$I$1845) -> 6345680 | Y13: =X13/$R$4 -> 1 | Z13: =Y13-Y12 -> 0.0078273723 | AA13: =SUMIF($P$2:$P$1845,$S13,$J$2:$J$1845)/W13 -> 87.884982 | AB13: =AA13*Y13 -> 87.884982 | AD13: =AA13*W13 -> 737371.7 | AE13: =AD13/SUM($AD$9:$AD$14) -> 0.029075349
A14: 97 | B14: 893 | C14: 1651 | D14: 1.01 | E14: 50260 | F14: 0 | G14: 50260000 | H14: 427 | I14: 33500 | J14: =I14*D14 -> 33835 | K14: 13 | L14: =SUM($I$2:$I14) -> 528100 | M14: =SUM($J$2:$J14) -> 1109474 | N14: =SUM($D$2:$D14) -> 27.48 | O14: =N14/$T$4 -> 0.0016376268 | P14: {=SUMPRODUCT((O14>$T$9:$T$14)*(O14<=$U$9:$U$14),$S$9:$S$14)} -> 1 | AD14: =AA14*W14 -> 0 | AE14: =AD14/SUM($AD$9:$AD$14) -> 0
A15: 889 | B15: 515 | C15: 150 | D15: 2.99 | E15: 10137 | F15: 0 | G15: 10137000 | H15: QEW | I15: 33300 | J15: =I15*D15 -> 99567 | K15: 14 | L15: =SUM($I$2:$I15) -> 561400 | M15: =SUM($J$2:$J15) -> 1209041 | N15: =SUM($D$2:$D15) -> 30.47 | O15: =N15/$T$4 -> 0.0018158111 | P15: {=SUMPRODUCT((O15>$T$9:$T$14)*(O15<=$U$9:$U$14),$S$9:$S$14)} -> 1
A16: 1591 | B16: 1591 | C16: 2080 | D16: 1.91 | E16: 50219 | F16: 0 | G16: 50219000 | H16: 427 | I16: 33000 | J16: =I16*D16 -> 63030 | K16: 15 | L16: =SUM($I$2:$I16) -> 594400 | M16: =SUM($J$2:$J16) -> 1272071 | N16: =SUM($D$2:$D16) -> 32.38 | O16: =N16/$T$4 -> 0.0019296345 | P16: {=SUMPRODUCT((O16>$T$9:$T$14)*(O16<=$U$9:$U$14),$S$9:$S$14)} -> 1
A17: 1664 | B17: 1664 | C17: 2162 | D17: 1.73 | E17: 50210 | F17: 0 | G17: 50210000 | H17: 427 | I17: 32600 | J17: =I17*D17 -> 56398 | K17: 16 | L17: =SUM($I$2:$I17) -> 627000 | M17: =SUM($J$2:$J17) -> 1328469 | N17: =SUM($D$2:$D17) -> 34.11 | O17: =N17/$T$4 -> 0.0020327311 | P17: {=SUMPRODUCT((O17>$T$9:$T$14)*(O17<=$U$9:$U$14),$S$9:$S$14)} -> 1
A18: 43 | B18: 839 | C18: 1593 | D18: 2.12 | E18: 47680 | F18: 0 | G18: 47680000 | H18: 401 | I18: 32400 | J18: =I18*D18 -> 68688 | K18: 17 | L18: =SUM($I$2:$I18) -> 659400 | M18: =SUM($J$2:$J18) -> 1397157 | N18: =SUM($D$2:$D18) -> 36.23 | O18: =N18/$T$4 -> 0.0021590691 | P18: {=SUMPRODUCT((O18>$T$9:$T$14)*(O18<=$U$9:$U$14),$S$9:$S$14)} -> 1
A19: 1571 | B19: 1571 | C19: 2060 | D19: 3.2 | E19: 47656 | F19: 0 | G19: 47656000 | H19: 401 | I19: 32300 | J19: =I19*D19 -> 103360 | K19: 18 | L19: =SUM($I$2:$I19) -> 691700 | M19: =SUM($J$2:$J19) -> 1500517 | N19: =SUM($D$2:$D19) -> 39.43 | O19: =N19/$T$4 -> 0.002349768 | P19: {=SUMPRODUCT((O19>$T$9:$T$14)*(O19<=$U$9:$U$14),$S$9:$S$14)} -> 1
A20: 1661 | B20: 1661 | C20: 2159 | D20: 0.8 | E20: 47652 | F20: 0 | G20: 47652000 | H20: 401 | I20: 32300 | J20: =I20*D20 -> 25840 | K20: 19 | L20: =SUM($I$2:$I20) -> 724000 | M20: =SUM($J$2:$J20) -> 1526357 | N20: =SUM($D$2:$D20) -> 40.23 | O20: =N20/$T$4 -> 0.0023974427 | P20: {=SUMPRODUCT((O20>$T$9:$T$14)*(O20<=$U$9:$U$14),$S$9:$S$14)} -> 1
A21: 896 | B21: 522 | C21: 157 | D21: 0.4 | E21: 10129 | F21: 0 | G21: 10129000 | H21: QEW | I21: 32000 | J21: =I21*D21 -> 12800 | K21: 20 | L21: =SUM($I$2:$I21) -> 756000 | M21: =SUM($J$2:$J21) -> 1539157 | N21: =SUM($D$2:$D21) -> 40.63 | O21: =N21/$T$4 -> 0.0024212801 | P21: {=SUMPRODUCT((O21>$T$9:$T$14)*(O21<=$U$9:$U$14),$S$9:$S$14)} -> 1
A22: 1630 | B22: 1630 | C22: 2124 | D22: 2.03 | E22: 47654 | F22: 0 | G22: 47654000 | H22: 401 | I22: 31700 | J22: =I22*D22 -> 64351 | K22: 21 | L22: =SUM($I$2:$I22) -> 787700 | M22: =SUM($J$2:$J22) -> 1603508 | N22: =SUM($D$2:$D22) -> 42.66 | O22: =N22/$T$4 -> 0.0025422547 | P22: {=SUMPRODUCT((O22>$T$9:$T$14)*(O22<=$U$9:$U$14),$S$9:$S$14)} -> 1
A23: 115 | B23: 911 | C23: 1670 | D23: 0.3 | E23: 50205 | F23: 0 | G23: 50205000 | H23: 427 | I23: 31700 | J23: =I23*D23 -> 9510 | K23: 22 | L23: =SUM($I$2:$I23) -> 819400 | M23: =SUM($J$2:$J23) -> 1613018 | N23: =SUM($D$2:$D23) -> 42.96 | O23: =N23/$T$4 -> 0.0025601327 | P23: {=SUMPRODUCT((O23>$T$9:$T$14)*(O23<=$U$9:$U$14),$S$9:$S$14)} -> 1
A24: 1556 | B24: 388 | C24: 1533 | D24: 1.42 | E24: 47650 | F24: 0 | G24: 47650000 | H24: 401 | I24: 30400 | J24: =I24*D24 -> 43168 | K24: 23 | L24: =SUM($I$2:$I24) -> 849800 | M24: =SUM($J$2:$J24) -> 1656186 | N24: =SUM($D$2:$D24) -> 44.38 | O24: =N24/$T$4 -> 0.0026447554 | P24: {=SUMPRODUCT((O24>$T$9:$T$14)*(O24<=$U$9:$U$14),$S$9:$S$14)} -> 1
A25: 109 | B25: 905 | C25: 1663 | D25: 1.51 | E25: 47624 | F25: 0 | G25: 47624000 | H25: 401 | I25: 29900 | J25: =I25*D25 -> 45149 | K25: 24 | L25: =SUM($I$2:$I25) -> 879700 | M25: =SUM($J$2:$J25) -> 1701335 | N25: =SUM($D$2:$D25) -> 45.89 | O25: =N25/$T$4 -> 0.0027347414 | P25: {=SUMPRODUCT((O25>$T$9:$T$14)*(O25<=$U$9:$U$14),$S$9:$S$14)} -> 1
A26: 119 | B26: 915 | C26: 1674 | D26: 2.63 | E26: 47610 | F26: 0 | G26: 47610000 | H26: 401 | I26: 29700 | J26: =I26*D26 -> 78111 | K26: 25 | L26: =SUM($I$2:$I26) -> 909400 | M26: =SUM($J$2:$J26) -> 1779446 | N26: =SUM($D$2:$D26) -> 48.52 | O26: =N26/$T$4 -> 0.0028914721 | P26: {=SUMPRODUCT((O26>$T$9:$T$14)*(O26<=$U$9:$U$14),$S$9:$S$14)} -> 1
A27: 890 | B27: 516 | C27: 151 | D27: 1.59 | E27: 10135 | F27: 0 | G27: 10135000 | H27: QEW | I27: 29700 | J27: =I27*D27 -> 47223 | K27: 26 | L27: =SUM($I$2:$I27) -> 939100 | M27: =SUM($J$2:$J27) -> 1826669 | N27: =SUM($D$2:$D27) -> 50.11 | O27: =N27/$T$4 -> 0.0029862256 | P27: {=SUMPRODUCT((O27>$T$9:$T$14)*(O27<=$U$9:$U$14),$S$9:$S$14)} -> 1
A28: 898 | B28: 524 | C28: 159 | D28: 2.02 | E28: 10126 | F28: 0 | G28: 10126000 | H28: QEW | I28: 29600 | J28: =I28*D28 -> 59792 | K28: 27 | L28: =SUM($I$2:$I28) -> 968700 | M28: =SUM($J$2:$J28) -> 1886461 | N28: =SUM($D$2:$D28) -> 52.13 | O28: =N28/$T$4 -> 0.0031066043 | P28: {=SUMPRODUCT((O28>$T$9:$T$14)*(O28<=$U$9:$U$14),$S$9:$S$14)} -> 1
A29: 120 | B29: 916 | C29: 1675 | D29: 1.74 | E29: 47607 | F29: 0 | G29: 47607000 | H29: 401 | I29: 29600 | J29: =I29*D29 -> 51504 | K29: 28 | L29: =SUM($I$2:$I29) -> 998300 | M29: =SUM($J$2:$J29) -> 1937965 | N29: =SUM($D$2:$D29) -> 53.87 | O29: =N29/$T$4 -> 0.0032102968 | P29: {=SUMPRODUCT((O29>$T$9:$T$14)*(O29<=$U$9:$U$14),$S$9:$S$14)} -> 1
A30: 366 | B30: 1161 | C30: 2045 | D30: 4.65 | E30: 48263 | F30: 0 | G30: 48263000 | H30: 403 | I30: 29000 | J30: =I30*D30 -> 134850 | K30: 29 | L30: =SUM($I$2:$I30) -> 1027300 | M30: =SUM($J$2:$J30) -> 2072815 | N30: =SUM($D$2:$D30) -> 58.52 | O30: =N30/$T$4 -> 0.0034874061 | P30: {=SUMPRODUCT((O30>$T$9:$T$14)*(O30<=$U$9:$U$14),$S$9:$S$14)} -> 1
A31: 1680 | B31: 1680 | C31: 2179 | D31: 1.7 | E31: 47643 | F31: 0 | G31: 47643000 | H31: 401 | I31: 28800 | J31: =I31*D31 -> 48960 | K31: 30 | L31: =SUM($I$2:$I31) -> 1056100 | M31: =SUM($J$2:$J31) -> 2121775 | N31: =SUM($D$2:$D31) -> 60.22 | O31: =N31/$T$4 -> 0.0035887149 | P31: {=SUMPRODUCT((O31>$T$9:$T$14)*(O31<=$U$9:$U$14),$S$9:$S$14)} -> 1
A32: 1615 | B32: 1615 | C32: 2107 | D32: 1.13 | E32: 47647 | F32: 0 | G32: 47647000 | H32: 401 | I32: 28700 | J32: =I32*D32 -> 32431 | K32: 31 | L32: =SUM($I$2:$I32) -> 1084800 | M32: =SUM($J$2:$J32) -> 2154206 | N32: =SUM($D$2:$D32) -> 61.35 | O32: =N32/$T$4 -> 0.0036560555 | P32: {=SUMPRODUCT((O32>$T$9:$T$14)*(O32<=$U$9:$U$14),$S$9:$S$14)} -> 1
A33: 42 | B33: 838 | C33: 1592 | D33: 2.64 | E33: 50280 | F33: 0 | G33: 50280000 | H33: 427 | I33: 28600 | J33: =I33*D33 -> 75504 | K33: 32 | L33: =SUM($I$2:$I33) -> 1113400 | M33: =SUM($J$2:$J33) -> 2229710 | N33: =SUM($D$2:$D33) -> 63.99 | O33: =N33/$T$4 -> 0.0038133821 | P33: {=SUMPRODUCT((O33>$T$9:$T$14)*(O33<=$U$9:$U$14),$S$9:$S$14)} -> 1
A34: 1605 | B34: 1605 | C34: 2095 | D34: 1.62 | E34: 47629 | F34: 0 | G34: 47629000 | H34: 401 | I34: 28600 | J34: =I34*D34 -> 46332 | K34: 33 | L34: =SUM($I$2:$I34) -> 1142000 | M34: =SUM($J$2:$J34) -> 2276042 | N34: =SUM($D$2:$D34) -> 65.61 | O34: =N34/$T$4 -> 0.0039099234 | P34: {=SUMPRODUCT((O34>$T$9:$T$14)*(O34<=$U$9:$U$14),$S$9:$S$14)} -> 1
A35: 361 | B35: 1156 | C35: 2040 | D35: 1.43 | E35: 48305 | F35: 0 | G35: 48305000 | H35: 403 | I35: 28500 | J35: =I35*D35 -> 40755 | K35: 34 | L35: =SUM($I$2:$I35) -> 1170500 | M35: =SUM($J$2:$J35) -> 2316797 | N35: =SUM($D$2:$D35) -> 67.04 | O35: =N35/$T$4 -> 0.0039951419 | P35: {=SUMPRODUCT((O35>$T$9:$T$14)*(O35<=$U$9:$U$14),$S$9:$S$14)} -> 1
A36: 1451 | B36: 283 | C36: 1406 | D36: 2.03 | E36: 47642 | F36: 0 | G36: 47642000 | H36: 401 | I36: 28400 | J36: =I36*D36 -> 57652 | K36: 35 | L36: =SUM($I$2:$I36) -> 1198900 | M36: =SUM($J$2:$J36) -> 2374449 | N36: =SUM($D$2:$D36) -> 69.07 | O36: =N36/$T$4 -> 0.0041161166 | P36: {=SUMPRODUCT((O36>$T$9:$T$14)*(O36<=$U$9:$U$14),$S$9:$S$14)} -> 1
A37: 25 | B37: 821 | C37: 1574 | D37: 1.62 | E37: 47628 | F37: 0 | G37: 47628000 | H37: 401 | I37: 28200 | J37: =I37*D37 -> 45684 | K37: 36 | L37: =SUM($I$2:$I37) -> 1227100 | M37: =SUM($J$2:$J37) -> 2420133 | N37: =SUM($D$2:$D37) -> 70.69 | O37: =N37/$T$4 -> 0.0042126579 | P37: {=SUMPRODUCT((O37>$T$9:$T$14)*(O37<=$U$9:$U$14),$S$9:$S$14)} -> 1
A38: 1593 | B38: 1593 | C38: 2082 | D38: 3.76 | E38: 47695 | F38: 0 | G38: 47695000 | H38: 401 | I38: 28100 | J38: =I38*D38 -> 105656 | K38: 37 | L38: =SUM($I$2:$I38) -> 1255200 | M38: =SUM($J$2:$J38) -> 2525789 | N38: =SUM($D$2:$D38) -> 74.45 | O38: =N38/$T$4 -> 0.0044367291 | P38: {=SUMPRODUCT((O38>$T$9:$T$14)*(O38<=$U$9:$U$14),$S$9:$S$14)} -> 1
A39: 1667 | B39: 1667 | C39: 2165 | D39: 1.98 | E39: 47635 | F39: 0 | G39: 47635000 | H39: 401 | I39: 28100 | J39: =I39*D39 -> 55638 | K39: 38 | L39: =SUM($I$2:$I39) -> 1283300 | M39: =SUM($J$2:$J39) -> 2581427 | N39: =SUM($D$2:$D39) -> 76.43 | O39: =N39/$T$4 -> 0.004554724 | P39: {=SUMPRODUCT((O39>$T$9:$T$14)*(O39<=$U$9:$U$14),$S$9:$S$14)} -> 1
A40: 26 | B40: 822 | C40: 1575 | D40: 1.94 | E40: 47640 | F40: 0 | G40: 47640000 | H40: 401 | I40: 27900 | J40: =I40*D40 -> 54126 | K40: 39 | L40: =SUM($I$2:$I40) -> 1311200 | M40: =SUM($J$2:$J40) -> 2635553 | N40: =SUM($D$2:$D40) -> 78.37 | O40: =N40/$T$4 -> 0.0046703352 | P40: {=SUMPRODUCT((O40>$T$9:$T$14)*(O40<=$U$9:$U$14),$S$9:$S$14)} -> 1
...
