Workbook
Name BDSL_GJ_L: '[1]Conversion Factors'!$G$20
Name BDSL_GJ_L: '[1]Conversion Factors'!$G$20
Name BDSL_GJ_L: '[1]Conversion Factors'!$G$20
Name BDSL_GJ_L: '[1]Conversion Factors'!$G$20
Name BDSL_GJ_L: 'Conversion Factors'!$G$20
Name BOB_GJ_L: '[1]Conversion Factors'!$G$18
Name BOB_GJ_L: '[1]Conversion Factors'!$G$18
Name BOB_GJ_L: '[1]Conversion Factors'!$G$18
Name BOB_GJ_L: '[1]Conversion Factors'!$G$18
Name BOB_GJ_L: 'Conversion Factors'!$G$18
Name CAD2021_to_2020: '[1]Conversion Factors'!$R$15
Name CAD2021_to_2020: '[1]Conversion Factors'!$R$15
Name CAD2021_to_2020: '[1]Conversion Factors'!$R$15
Name CAD2021_to_2020: '[1]Conversion Factors'!$R$15
Name CAD2021_to_2020: 'Conversion Factors'!$R$15
Name CAD2022_to_2020: '[1]Conversion Factors'!$R$16
Name CAD2022_to_2020: '[1]Conversion Factors'!$R$16
Name CAD2022_to_2020: '[1]Conversion Factors'!$R$16
Name CAD2022_to_2020: '[1]Conversion Factors'!$R$16
Name CAD2022_to_2020: 'Conversion Factors'!$R$16
Name CNG_DGE: 'Conversion Factors'!$D$28
Name DGE_GGE: '[1]Conversion Factors'!$C$19
Name DGE_GGE: '[1]Conversion Factors'!$C$19
Name DGE_GGE: '[1]Conversion Factors'!$C$19
Name DGE_GGE: '[1]Conversion Factors'!$C$19
Name DGE_GGE: 'Conversion Factors'!$C$19
Name DSL_PJ_ML: '[1]Conversion Factors'!$G$15
Name DSL_PJ_ML: '[1]Conversion Factors'!$G$15
Name DSL_PJ_ML: '[1]Conversion Factors'!$G$15
Name DSL_PJ_ML: '[1]Conversion Factors'!$G$15
Name DSL_PJ_ML: 'Conversion Factors'!$G$15
Name E85_PJ_ML: 'Conversion Factors'!$G$16
Name ELC_PJ_MkWh: '[1]Conversion Factors'!$G$17
Name ELC_PJ_MkWh: '[1]Conversion Factors'!$G$17
Name ELC_PJ_MkWh: '[1]Conversion Factors'!$G$17
Name ELC_PJ_MkWh: '[1]Conversion Factors'!$G$17
Name ELC_PJ_MkWh: 'Conversion Factors'!$G$17
Name ETH_GJ_L: '[1]Conversion Factors'!$G$19
Name ETH_GJ_L: '[1]Conversion Factors'!$G$19
Name ETH_GJ_L: '[1]Conversion Factors'!$G$19
Name ETH_GJ_L: '[1]Conversion Factors'!$G$19
Name ETH_GJ_L: 'Conversion Factors'!$G$19
Name GBP2020_to_CAD2020: '[1]Conversion Factors'!$R$17
Name GBP2020_to_CAD2020: '[1]Conversion Factors'!$R$17
Name GBP2020_to_CAD2020: '[1]Conversion Factors'!$R$17
Name GBP2020_to_CAD2020: '[1]Conversion Factors'!$R$17
Name GBP2020_to_CAD2020: 'Conversion Factors'!$R$17
Name GGE_DGE: 'Conversion Factors'!$D$18
Name GSL_PJ_ML: '[1]Conversion Factors'!$G$14
Name GSL_PJ_ML: '[1]Conversion Factors'!$G$14
Name GSL_PJ_ML: '[1]Conversion Factors'!$G$14
Name GSL_PJ_ML: '[1]Conversion Factors'!$G$14
Name GSL_PJ_ML: 'Conversion Factors'!$G$14
Name GWy_PJ: '[1]Conversion Factors'!$G$27
Name GWy_PJ: '[1]Conversion Factors'!$G$27
Name GWy_PJ: '[1]Conversion Factors'!$G$27
Name GWy_PJ: '[1]Conversion Factors'!$G$27
Name GWy_PJ: 'Conversion Factors'!$G$27
Name H2_HHV_by_LHV: '[1]Conversion Factors'!$D$14
Name H2_HHV_by_LHV: '[1]Conversion Factors'!$D$14

Sheet Overview
C1: **********************************************************************************************************************
C2: Canadian Open Energy Model
C3: Transportation Sector Database
C4: Province of Ontario
C6: Sustainable Systems Group
C7: Dept. of Civil and Mineral Engineering
C8: University of Toronto
C10: Authored by: Felipe Rashid Zetter Salcedo
C11: MASc Thesis Project
C12: Last update: August 2024
C14: Supervised by: Prof. Daniel Posen & Prof. Heather McLean
C15: Contact: rashidzetter@gmail.com
... C28: Cell color scheme
A29: Cell | C29: Description
C30: Highlighted values in this color across the model sheets denote those that are used for input parameter calculations. Note that not all the values used for calculations have been highlighted.
C31: Highlighted values in this color denote orphan parameters that are currently not used, but could be in future versions.
C32: Highlighted values in this color denote high uncertainty parameters that need revision.
C34: Sheet descriptions
A35: Sheet | C35: Description
C36: Contains the list of technologies and commodities that will be compiled and used by Temoa.
C37: Harmonized input parameters; ready to be compiled into the SQLite database used by Temoa. The ready-for-input table is located on the far left side of the sheet. At the right side of the ready-for-input table are the calculations.
C38: Compilation of input parameters and the underlying data tables used to run the stochastic aggregation of electric vehicle charging demand with RAMP-mobility.
C39: Compilation of original data tables used for the calculation of harmonized parameters, mostly from the NRCan Energy Use Database, other Canadian sources, and US sources.
C40: Original datasets from other large models, located in separate sheets to differentiate by source, used for the calculation of harmonized parameters.
C41: Contains the conversion factors used across the parameter calculations. Including GREET heating values, unit conversions, currency inflated exchange rates, and inflation indexes.
C42: Contains the list of main database assumptions and all references used.
C44: Data Quality Indicators (DQIs)
C45: Each DQI is given a score of 1 to 5 upon evaluation of data quality, 1 being the best score and 5 being the worse. Based on Table 5-2 from NRC-EME-56367 report.
C47: Reliability: provides indication of quality of data collection and validation methods.
C48: Representativeness: evaluates the robustness of sampling methods and the amount of data points collected.
C49: Temporal: time-related appropiateness measuring the age of the data.
... C51: Technological: measures the gap between goal and scope of the model and the actually-represented technology.

Sheet Technology
A1: tech | B1: flag | C1: sector | D1: description | E1: additional_notes | F1: category | G1: unlim_cap | H1: annual | I1: cf_fixed
A2: T_HDV_T_LH_CHRG_LRGBATT | B2: p | C2: Transport | D2: Charging infrastructure for on-road heavy-duty vehicles long-haul freight trucks large batteries | F2: Charging | G2: 0 | H2: 0
A3: T_HDV_T_LH_CHRG_FSTCHRG | B3: p | C3: Transport | D3: Charging infrastructure for on-road heavy-duty vehicles long-haul freight trucks fast chargers | F3: Charging | G3: 0 | H3: 0
A4: T_HDV_T_LH_CHRG_ERDS1 | B4: p | C4: Transport | D4: Charging infrastructure for on-road heavy-duty vehicles long-haul freight trucks eRoads bin 1 | F4: Charging | G4: 0 | H4: 0
A5: T_HDV_T_LH_CHRG_ERDS2 | B5: p | C5: Transport | D5: Charging infrastructure for on-road heavy-duty vehicles long-haul freight trucks eRoads bin 2 | F5: Charging | G5: 0 | H5: 0
A6: T_HDV_T_LH_CHRG_ERDS3 | B6: p | C6: Transport | D6: Charging infrastructure for on-road heavy-duty vehicles long-haul freight trucks eRoads bin 3 | F6: Charging | G6: 0 | H6: 0
A7: T_HDV_T_LH_CHRG_ERDS4 | B7: p | C7: Transport | D7: Charging infrastructure for on-road heavy-duty vehicles long-haul freight trucks eRoads bin 4 | F7: Charging | G7: 0 | H7: 0
A8: T_HDV_T_LH_CHRG_ERDS5 | B8: p | C8: Transport | D8: Charging infrastructure for on-road heavy-duty vehicles long-haul freight trucks eRoads bin 5 | F8: Charging | G8: 0 | H8: 0
A9: T_H2_HDV_T_LH_REFUEL | B9: p | C9: Transport | D9: Hydrogen refuelling station for on-road heavy-duty vehicles long-haul freight trucks | F9: H2 refuelling | G9: 0 | H9: 0
A10: T_HDV_T_LH_DSL_EX | B10: p | C10: Transport | D10: Existing heavy-duty long-haul freight truck (diesel) | E10: Vehicle class corresponds to “Heavy Trucks” from NRCan Comprehensive Energy Use Database 2024; a truck with a gross weight of more than 33,000 lb (class 8). | F10: Heavy trucks | G10: 0 | H10: 1
A11: T_HDV_T_LH_DSL_N | B11: p | C11: Transport | D11: New heavy-duty long-haul freight truck (diesel) | E11: Vehicle class corresponds to “Heavy Trucks” from NRCan Comprehensive Energy Use Database 2024; a truck with a gross weight of more than 33,000 lb (class 8). | F11: Heavy trucks | G11: 0 | H11: 1
A12: T_HDV_T_LH_FCEV_N | B12: p | C12: Transport | D12: New heavy-duty long-haul freight truck (fuel cell electric, gaseous H2 @ 700 bar) | E12: Vehicle class corresponds to “Heavy Trucks” from NRCan Comprehensive Energy Use Database 2024; a truck with a gross weight of more than 33,000 lb (class 8). | F12: Heavy trucks | G12: 0 | H12: 0
A13: T_HDV_T_LH_BEV_LRGBATT_N | B13: p | C13: Transport | D13: New heavy-duty long-haul freight truck (battery electric) large batteries | E13: Vehicle class corresponds to “Heavy Trucks” from NRCan Comprehensive Energy Use Database 2024; a truck with a gross weight of more than 33,000 lb (class 8). | F13: Heavy trucks | G13: 0 | H13: 0
A14: T_HDV_T_LH_BEV_FSTCHRG_N | B14: p | C14: Transport | D14: New heavy-duty long-haul freight truck (battery electric) fast chargers | E14: Vehicle class corresponds to “Heavy Trucks” from NRCan Comprehensive Energy Use Database 2024; a truck with a gross weight of more than 33,000 lb (class 8). | F14: Heavy trucks | G14: 0 | H14: 0
A15: T_HDV_T_LH_BEV_ERDS1_N | B15: p | C15: Transport | D15: New heavy-duty long-haul freight truck (battery electric) eRoads bin 1 | E15: Vehicle class corresponds to “Heavy Trucks” from NRCan Comprehensive Energy Use Database 2024; a truck with a gross weight of more than 33,000 lb (class 8). | F15: Heavy trucks | G15: 0 | H15: 0
A16: T_HDV_T_LH_BEV_ERDS2_N | B16: p | C16: Transport | D16: New heavy-duty long-haul freight truck (battery electric) eRoads bin 2 | E16: Vehicle class corresponds to “Heavy Trucks” from NRCan Comprehensive Energy Use Database 2024; a truck with a gross weight of more than 33,000 lb (class 8). | F16: Heavy trucks | G16: 0 | H16: 0
A17: T_HDV_T_LH_BEV_ERDS3_N | B17: p | C17: Transport | D17: New heavy-duty long-haul freight truck (battery electric) eRoads bin 3 | E17: Vehicle class corresponds to “Heavy Trucks” from NRCan Comprehensive Energy Use Database 2024; a truck with a gross weight of more than 33,000 lb (class 8). | F17: Heavy trucks | G17: 0 | H17: 0
A18: T_HDV_T_LH_BEV_ERDS4_N | B18: p | C18: Transport | D18: New heavy-duty long-haul freight truck (battery electric) eRoads bin 4 | E18: Vehicle class corresponds to “Heavy Trucks” from NRCan Comprehensive Energy Use Database 2024; a truck with a gross weight of more than 33,000 lb (class 8). | F18: Heavy trucks | G18: 0 | H18: 0
A19: T_HDV_T_LH_BEV_ERDS5_N | B19: p | C19: Transport | D19: New heavy-duty long-haul freight truck (battery electric) eRoads bin 5 | E19: Vehicle class corresponds to “Heavy Trucks” from NRCan Comprehensive Energy Use Database 2024; a truck with a gross weight of more than 33,000 lb (class 8). | F19: Heavy trucks | G19: 0 | H19: 0
A20: T_dummy_tkm_hdv_t_lh | B20: p | C20: Transport | D20: Dummy tech used to release non-profiled vehicles from charging demand distribution | F20: Heavy trucks | G20: 1 | H20: 1

Sheet Commodity
A1: name | B1: flag | C1: description | D1: additional_notes
A2: T_D_tkm_hdv_t_lh | B2: d | C2: Demand for total tonne-kilometers driven by heavy-duty trucks, long-haul | D2: billion tonne-km
A3: T_elc_hdv_t_lh_chrg_lrgbatt | B3: p | C3: Electricity from heavy-duty EV charger, long-haul freight trucks, large batteries | D3: PJ
A4: T_elc_hdv_t_lh_chrg_fstchrg | B4: p | C4: Electricity from heavy-duty EV charger, long-haul freight trucks, fast chargers | D4: PJ
A5: T_elc_hdv_t_lh_chrg_erds1 | B5: p | C5: Electricity from heavy-duty EV charger, long-haul freight trucks, eRoads bin 1 | D5: PJ
A6: T_elc_hdv_t_lh_chrg_erds2 | B6: p | C6: Electricity from heavy-duty EV charger, long-haul freight trucks, eRoads bin 2 | D6: PJ
A7: T_elc_hdv_t_lh_chrg_erds3 | B7: p | C7: Electricity from heavy-duty EV charger, long-haul freight trucks, eRoads bin 3 | D7: PJ
A8: T_elc_hdv_t_lh_chrg_erds4 | B8: p | C8: Electricity from heavy-duty EV charger, long-haul freight trucks, eRoads bin 4 | D8: PJ
A9: T_elc_hdv_t_lh_chrg_erds5 | B9: p | C9: Electricity from heavy-duty EV charger, long-haul freight trucks, eRoads bin 5 | D9: PJ
A10: T_h2_hdv_t_lh | B10: p | C10: Gaseous H2 @ 700 bar for use in heavy-duty vehicles, long-haul freight trucks | D10: PJ
A11: T_annual_tkm_hdv_t_lh | B11: a | C11: Dummy annual commodity (flag='a') used to release non-profiled vehicles from charging demand distribution | D11: billion tonne-km

Sheet ExistingCapacity
F1: vintage | AB1: DQI | AG1: Model input | AI1: Input calculations | AJ1: LDV market share by vehicle class and technology type in Ontario | BG1: ON Ministry of Transportation - 2020 fleet registration data by age and class
A2: tech | B2: region | C2: reference | D2: data_year | E2: units | F2: 2000 | G2: 2001 | H2: 2002 | I2: 2003 | J2: 2004 | K2: 2005 | L2: 2006 | M2: 2007 | N2: 2008 | O2: 2009 | P2: 2010 | Q2: 2011 | R2: 2012 | S2: 2013 | T2: 2014 | U2: 2015 | V2: 2016 | W2: 2017 | X2: 2018 | Y2: 2019 | Z2: 2020 | AA2: notes | AB2: Reliability | AC2: Representativeness | AD2: Temporal | AE2: Geographical | AF2: Technological | AJ2: Vehicle type | AK2: Downscaling Source | AL2: 2005 | AM2: 2006 | AN2: 2007 | AO2: 2008 | AP2: 2009 | AQ2: 2010 | AR2: 2011 | AS2: 2012 | AT2: 2013 | AU2: 2014 | AV2: 2015 | AW2: 2016 | AX2: 2017 | AY2: 2018 | AZ2: 2019 | BA2: 2020 | BB2: 2021 | BC2: 2022 | BD2: 2023 | BE2: Conv. veh. market share change | BG2: Registered class | BH2: 2003 | BI2: 2004 | BJ2: 2005 | BK2: 2006 | BL2: 2007 | BM2: 2008 | BN2: 2009 | BO2: 2010 | BP2: 2011 | BQ2: 2012 | BR2: 2013 | BS2: 2014 | BT2: 2015 | BU2: 2016 | BV2: 2017 | BW2: 2018 | BX2: 2019 | BY2: 2020 | BZ2: 2021
A3: T_HDV_T_DSL_EX | B3: ON | C3: Natural Resources Canada. (2023b). Transportation Sector – Ontario. Government of Canada, Natural Resources Canada. https://oee.nrcan.gc.ca/corporate/statistics/neud/dpa/menus/trends/comprehensive/trends_tran_on.cfm | D3: 2023 | E3: k units | K3: =(1-CFAF!$E$3)*SUMIF($BH$3:$BY$3,K$2,$BH$16:$BY$16) -> 6.2663437 | P3: =(1-CFAF!$E$3)*SUMIF($BH$3:$BY$3,P$2,$BH$16:$BY$16) -> 17.233369 | U3: =(1-CFAF!$E$3)*SUMIF($BH$3:$BY$3,U$2,$BH$16:$BY$16) -> 22.965776 | Z3: =(1-CFAF!$E$3)*SUMIF($BH$3:$BY$3,Z$2,$BH$16:$BY$16) -> 40.184767 | AA3: Vehicle class 2021 fleet stock was distributed across vintages up to 2020 based on commercial vehicle registrations by age (ON Ministry of Transportation, 2023). Ontario long-haul/short-haul split from Canadian Freight Analysis Framework 2017 data. | AB3: 1 | AC3: 1 | AD3: 1 | AE3: 1 | AF3: 1 | BG3: Aggregated vintage | BH3: 2005 | BI3: 2005 | BJ3: =BJ2 -> 2005 | BK3: 2010 | BL3: 2010 | BM3: 2010 | BN3: 2010 | BO3: 2010 | BP3: 2015 | BQ3: 2015 | BR3: 2015 | BS3: 2015 | BT3: 2015 | BU3: 2020 | BV3: 2020 | BW3: 2020 | BX3: 2020 | BY3: 2020
A4: T_HDV_T_LH_DSL_EX | B4: ON | C4: Natural Resources Canada. (2023b). Transportation Sector – Ontario. Government of Canada, Natural Resources Canada. https://oee.nrcan.gc.ca/corporate/statistics/neud/dpa/menus/trends/comprehensive/trends_tran_on.cfm | D4: 2023 | E4: k units | K4: =(CFAF!$E$3)*SUMIF($BH$3:$BY$3,K$2,$BH$16:$BY$16) -> 3.4640036 | P4: =(CFAF!$E$3)*SUMIF($BH$3:$BY$3,P$2,$BH$16:$BY$16) -> 9.5265207 | U4: =(CFAF!$E$3)*SUMIF($BH$3:$BY$3,U$2,$BH$16:$BY$16) -> 12.695367 | Z4: =(CFAF!$E$3)*SUMIF($BH$3:$BY$3,Z$2,$BH$16:$BY$16) -> 22.21394 | AA4: Vehicle class 2021 fleet stock was distributed across vintages up to 2020 based on commercial vehicle registrations by age (ON Ministry of Transportation, 2023). Ontario long-haul/short-haul split from Canadian Freight Analysis Framework 2017 data. | AB4: 1 | AC4: 1 | AD4: 1 | AE4: 1 | AF4: 1 | AJ4: Cars | AK4: (StatCan, 2023) Table: 20-10-0021-01 | AR4: ='Background Data'!AD66-'Background Data'!AD72 -> 247563 | AS4: ='Background Data'!AE66-'Background Data'!AE72 -> 265280 | AT4: ='Background Data'!AF66-'Background Data'!AF72 -> 277662 | AU4: ='Background Data'!AG66-'Background Data'!AG72 -> 277922 | AV4: ='Background Data'!AH66-'Background Data'!AH72 -> 267263 | AW4: ='Background Data'!AI66-'Background Data'!AI72 -> 249770 | AX4: ='Background Data'!AJ66-'Background Data'!AJ72 -> 253252 | AY4: ='Background Data'!AK66-'Background Data'!AK72 -> 240525 | ... BD4: ='Background Data'!AP66-'Background Data'!AP72 -> 110562 | BG4: Vehicle Age (in 2021) | BH4: =2021-BH2 -> 18 | BI4: =2021-BI2 -> 17 | BJ4: =2021-BJ2 -> 16 | BK4: =2021-BK2 -> 15 | BL4: =2021-BL2 -> 14 | BM4: =2021-BM2 -> 13 | BN4: =2021-BN2 -> 12 | BO4: =2021-BO2 -> 11 | ... BY4: =2021-BY2 -> 1 | BZ4: 0
AJ5: Gasoline | AN5: 0.97 | AO5: 0.97 | AP5: 0.97 | AQ5: 0.97 | AR5: ='Background Data'!AD67/AR$4 -> 0.95873778 | AS5: ='Background Data'!AE67/AS$4 -> 0.94412319 | AT5: ='Background Data'!AF67/AT$4 -> 0.94165928 | AU5: ='Background Data'!AG67/AU$4 -> 0.93791783 | AV5: ='Background Data'!AH67/AV$4 -> 0.95077882 | AW5: ='Background Data'!AI67/AW$4 -> 0.96515995 | AX5: ='Background Data'!AJ67/AX$4 -> 0.9530981 | AY5: ='Background Data'!AK67/AY$4 -> 0.92406195 | ... BD5: ='Background Data'!AP67/BD$4 -> 0.80563847 | BE5: =1 - BD5/AZ5 -> 0.13105422 | BG5: Passenger registrations | BK5: 171090 | BL5: 222416 | BM5: 255644 | BN5: 262822 | BO5: 347718 | BP5: 325214 | BQ5: 369730 | BR5: 420215 | BS5: 425526 | BT5: 489953 | BU5: 486871 | BV5: 543758 | BW5: 534711 | BX5: 517396 | BY5: 422696 | BZ5: 430762
AJ6: Diesel | AN6: 0.03 | AO6: 0.03 | AP6: 0.03 | AQ6: 0.03 | AR6: ='Background Data'!AD68/AR$4 -> 0.026461951 | AS6: ='Background Data'!AE68/AS$4 -> 0.028848764 | AT6: ='Background Data'!AF68/AT$4 -> 0.029146948 | AU6: ='Background Data'!AG68/AU$4 -> 0.032861738 | AV6: ='Background Data'!AH68/AV$4 -> 0.023141999 | AW6: ='Background Data'!AI68/AW$4 -> 0.0036073187 | AX6: ='Background Data'!AJ68/AX$4 -> 0.0030207066 | AY6: ='Background Data'!AK68/AY$4 -> 0.0029352458 | ... BD6: ='Background Data'!AP68/BD$4 -> 0 | BG6: Distribution (>2008) | BM6: =BM5/SUM($BM$5:$BZ$5) -> 0.04382707 | BN6: =BN5/SUM($BM$5:$BZ$5) -> 0.045057651 | BO6: =BO5/SUM($BM$5:$BZ$5) -> 0.059612043 | BP6: =BP5/SUM($BM$5:$BZ$5) -> 0.055754004 | BQ6: =BQ5/SUM($BM$5:$BZ$5) -> 0.063385734 | BR6: =BR5/SUM($BM$5:$BZ$5) -> 0.072040776 | BS6: =BS5/SUM($BM$5:$BZ$5) -> 0.072951283 | BT6: =BT5/SUM($BM$5:$BZ$5) -> 0.083996512 | ... BZ6: =BZ5/SUM($BM$5:$BZ$5) -> 0.073848932
AJ7: Battery electric | AN7: 0 | AO7: 0 | AP7: 0 | AQ7: 0 | AR7: ='Background Data'!AD69/AR$4 -> 0.00026255943 | AS7: ='Background Data'!AE69/AS$4 -> 0.00070491556 | AT7: ='Background Data'!AF69/AT$4 -> 0.0022113217 | AU7: ='Background Data'!AG69/AU$4 -> 0.0038715899 | AV7: ='Background Data'!AH69/AV$4 -> 0.0045423422 | AW7: ='Background Data'!AI69/AW$4 -> 0.0037234256 | AX7: ='Background Data'!AJ69/AX$4 -> 0.0099979467 | AY7: ='Background Data'!AK69/AY$4 -> 0.030396009 | ... BD7: ='Background Data'!AP69/BD$4 -> 0.092011722 | BG7: 2021 car fleet (k units) | BM7: ='Background Data'!$X$11*BM6 -> 180.55727 | BN7: ='Background Data'!$X$11*BN6 -> 185.62698 | BO7: ='Background Data'!$X$11*BO6 -> 245.58767 | BP7: ='Background Data'!$X$11*BP6 -> 229.69345 | BQ7: ='Background Data'!$X$11*BQ6 -> 261.13439 | BR7: ='Background Data'!$X$11*BR6 -> 296.79114 | BS7: ='Background Data'!$X$11*BS6 -> 300.54221 | BT7: ='Background Data'!$X$11*BT6 -> 346.04598 | ... BY7: ='Background Data'!$X$11*BY6 -> 298.54343
AJ8: Hybrid electric | AN8: 0 | AO8: 0 | AP8: 0 | AQ8: 0 | AR8: ='Background Data'!AD70/AR$4 -> 0.013879295 | AS8: ='Background Data'!AE70/AS$4 -> 0.024690893 | AT8: ='Background Data'!AF70/AT$4 -> 0.025282538 | AU8: ='Background Data'!AG70/AU$4 -> 0.023046034 | AV8: ='Background Data'!AH70/AV$4 -> 0.018917695 | AW8: ='Background Data'!AI70/AW$4 -> 0.019333787 | AX8: ='Background Data'!AJ70/AX$4 -> 0.019435187 | AY8: ='Background Data'!AK70/AY$4 -> 0.019669473 | ... BD8: ='Background Data'!AP70/BD$4 -> 0.094878891 | BE8: =BD8/AZ8 - 1 -> 1.5317936 | BG8: Distribution (>2006) | BK8: =BK5/SUM($BK$5:$BZ$5) -> 0.027477619 | BL8: =BL5/SUM($BK$5:$BZ$5) -> 0.035720744 | BM8: =BM5/SUM($BK$5:$BZ$5) -> 0.041057271 | BN8: =BN5/SUM($BK$5:$BZ$5) -> 0.042210081 | BO8: =BO5/SUM($BK$5:$BZ$5) -> 0.055844659 | BP8: =BP5/SUM($BK$5:$BZ$5) -> 0.052230443 | BQ8: =BQ5/SUM($BK$5:$BZ$5) -> 0.059379859 | BR8: =BR5/SUM($BK$5:$BZ$5) -> 0.067487917 | ... BZ8: =BZ5/SUM($BK$5:$BZ$5) -> 0.0691818
AJ9: Plug-in hybrid electric | AN9: 0 | AO9: 0 | AP9: 0 | AQ9: 0 | AR9: ='Background Data'!AD71/AR$4 -> 0.00065841826 | AS9: ='Background Data'!AE71/AS$4 -> 0.0016322376 | AT9: ='Background Data'!AF71/AT$4 -> 0.0016999085 | AU9: ='Background Data'!AG71/AU$4 -> 0.0023028044 | AV9: ='Background Data'!AH71/AV$4 -> 0.0026191429 | AW9: ='Background Data'!AI71/AW$4 -> 0.0081755215 | AX9: ='Background Data'!AJ71/AX$4 -> 0.01444806 | AY9: ='Background Data'!AK71/AY$4 -> 0.022937325 | ... BD9: ='Background Data'!AP71/BD$4 -> 0.0074709213 | BG9: 2021 LT fleet (k units) | BK9: ='Background Data'!$X$12*BK8 -> 113.00069 | BL9: ='Background Data'!$X$12*BL8 -> 146.90024 | BM9: ='Background Data'!$X$12*BM8 -> 168.84651 | BN9: ='Background Data'!$X$12*BN8 -> 173.5874 | BO9: ='Background Data'!$X$12*BO8 -> 229.6591 | BP9: ='Background Data'!$X$12*BP8 -> 214.79576 | BQ9: ='Background Data'!$X$12*BQ8 -> 244.19747 | BR9: ='Background Data'!$X$12*BR8 -> 277.54156 | ... BY9: ='Background Data'!$X$12*BY8 -> 279.1802
AJ10: Pickup Trucks (Light/Medium Trucks) | AR10: ='Background Data'!AD73-'Background Data'!AD76-'Background Data'!AD78-'Background Data'!AD79 -> 78026 | AS10: ='Background Data'!AE73-'Background Data'!AE76-'Background Data'!AE78-'Background Data'!AE79 -> 66686 | AT10: ='Background Data'!AF73-'Background Data'!AF76-'Background Data'!AF78-'Background Data'!AF79 -> 80401 | AU10: ='Background Data'!AG73-'Background Data'!AG76-'Background Data'!AG78-'Background Data'!AG79 -> 86768 | AV10: ='Background Data'!AH73-'Background Data'!AH76-'Background Data'!AH78-'Background Data'!AH79 -> 104178 | AW10: ='Background Data'!AI73-'Background Data'!AI76-'Background Data'!AI78-'Background Data'!AI79 -> 126823 | AX10: ='Background Data'!AJ73-'Background Data'!AJ76-'Background Data'!AJ78-'Background Data'!AJ79 -> 144063 | AY10: ='Background Data'!AK73-'Background Data'!AK76-'Background Data'!AK78-'Background Data'!AK79 -> 135361 | ... BA10: ='Background Data'!AM73-'Background Data'!AM76-'Background Data'!AM78-'Background Data'!AM79 -> 127770 | BB10: ='Background Data'!AN73 -'Background Data'!AN79 -> 117894 | BC10: ='Background Data'!AO73 -'Background Data'!AO79 -> 122767 | BD10: ='Background Data'!AP73 -'Background Data'!AP79 -> 127652 | BG10: Commercial registrations | BH10: 26945 | BI10: 30185 | BJ10: 36137 | BK10: 42697 | BL10: 52407 | BM10: 53633 | BN10: 44846 | BO10: 62915 | BP10: 68877 | BQ10: 59224 | BR10: 60904 | BS10: 71922 | BT10: 80891 | BU10: 100677 | BV10: 117816 | BW10: 123742 | BX10: 143314 | BY10: 112553 | BZ10: 129859
AJ11: Gasoline | AL11: The lifetime of cars, light trucks, and medium trucks is assumed to be 14 and 16 years, respectively. Since the available market shares with fuel type resolution are only available from 2011-2021, the remaining market shares of gasoline vehicles are assumed to remain constant based on the 2011 shares. Diesel is assumed to account for the entire remaining share. MDVs are represented with registered vehicles instead, as only diesel and gasoline fuel types are reported. | AR11: ='Background Data'!AD74/AR$10 -> 0.93075385 | AS11: ='Background Data'!AE74/AS$10 -> 0.92463186 | AT11: ='Background Data'!AF74/AT$10 -> 0.93408042 | AU11: ='Background Data'!AG74/AU$10 -> 0.90168034 | AV11: ='Background Data'!AH74/AV$10 -> 0.893394 | AW11: ='Background Data'!AI74/AW$10 -> 0.88861642 | AX11: ='Background Data'!AJ74/AX$10 -> 0.91154564 | AY11: ='Background Data'!AK74/AY$10 -> 0.88623015 | ... BD11: ='Background Data'!AP74/BD$10 -> 0.809059 | BG11: Distribution (>2006) | BK11: =BK10/SUM($BK$10:$BZ$10) -> 0.032193124 | BL11: =BL10/SUM($BK$10:$BZ$10) -> 0.03951437 | BM11: =BM10/SUM($BK$10:$BZ$10) -> 0.040438762 | BN11: =BN10/SUM($BK$10:$BZ$10) -> 0.033813449 | BO11: =BO10/SUM($BK$10:$BZ$10) -> 0.0474373 | BP11: =BP10/SUM($BK$10:$BZ$10) -> 0.05193259 | BQ11: =BQ10/SUM($BK$10:$BZ$10) -> 0.044654322 | BR11: =BR10/SUM($BK$10:$BZ$10) -> 0.045921026 | ... BZ11: =BZ10/SUM($BK$10:$BZ$10) -> 0.097912427
AJ12: Diesel | AR12: ='Background Data'!AD75/AR$10 -> 0.068387461 | AS12: ='Background Data'!AE75/AS$10 -> 0.0744834 | AT12: ='Background Data'!AF75/AT$10 -> 0.065807639 | AU12: ='Background Data'!AG75/AU$10 -> 0.098308132 | AV12: ='Background Data'!AH75/AV$10 -> 0.106606 | AW12: ='Background Data'!AI75/AW$10 -> 0.11138358 | AX12: ='Background Data'!AJ75/AX$10 -> 0.088454357 | AY12: ='Background Data'!AK75/AY$10 -> 0.11376985 | ... BD12: ='Background Data'!AP75/BD$10 -> 0.14190142 | BG12: 2021 LT fleet (k units) | BK12: ='Background Data'!$X$13*BK11 -> 36.996177 | BL12: ='Background Data'!$X$13*BL11 -> 45.409716 | BM12: ='Background Data'!$X$13*BM11 -> 46.472023 | BN12: ='Background Data'!$X$13*BN11 -> 38.858247 | BO12: ='Background Data'!$X$13*BO11 -> 54.514708 | BP12: ='Background Data'!$X$13*BP11 -> 59.680673 | BQ12: ='Background Data'!$X$13*BQ11 -> 51.316523 | BR12: ='Background Data'!$X$13*BR11 -> 52.772213 | ... BY12: ='Background Data'!$X$13*BY11 -> 97.525136
AJ13: Battery electric | AR13: ='Background Data'!AD76/AR$10 -> 0 | AS13: ='Background Data'!AE76/AS$10 -> 0 | AT13: ='Background Data'!AF76/AT$10 -> 0 | AU13: ='Background Data'!AG76/AU$10 -> 0 | AV13: ='Background Data'!AH76/AV$10 -> 0 | AW13: ='Background Data'!AI76/AW$10 -> 0 | AX13: ='Background Data'!AJ76/AX$10 -> 0 | AY13: ='Background Data'!AK76/AY$10 -> 0 | ... BD13: ='Background Data'!AP76/BD$10 -> 0.014171341 | BG13: Distribution (>2004) | BI13: 0.021675299 | BJ13: 0.025949322 | BK13: 0.030659939 | BL13: 0.037632513 | BM13: 0.038512881 | BN13: 0.032203097 | BO13: 0.045178117 | BP13: 0.04945932 | BQ13: 0.042527677 | BR13: 0.043734054 | BS13: 0.051645879 | BT13: 0.058086355 | BU13: 0.072294322 | BV13: 0.084601526 | BW13: 0.088856878 | BX13: 0.10291118 | BY13: 0.080822261 | BZ13: 0.080822261
AJ14: Hybrid electric | AR14: ='Background Data'!AD77/AR$10 -> 0.00085868813 | AS14: ='Background Data'!AE77/AS$10 -> 0.00088474342 | AT14: ='Background Data'!AF77/AT$10 -> 0.00011193891 | AU14: ='Background Data'!AG77/AU$10 -> 1.1524986e-05 | AV14: ='Background Data'!AH77/AV$10 -> 0 | AW14: ='Background Data'!AI77/AW$10 -> 0 | AX14: ='Background Data'!AJ77/AX$10 -> 0 | AY14: ='Background Data'!AK77/AY$10 -> 0 | ... BD14: ='Background Data'!AP77/BD$10 -> 0.034868236 | BG14: 2021 MT fleet (k units) | BI14: ='Background Data'!$X$14*BI13 -> 9.1603716 | BJ14: ='Background Data'!$X$14*BJ13 -> 10.966651 | BK14: ='Background Data'!$X$14*BK13 -> 12.957442 | BL14: ='Background Data'!$X$14*BL13 -> 15.904177 | BM14: ='Background Data'!$X$14*BM13 -> 16.276237 | BN14: ='Background Data'!$X$14*BN13 -> 13.609608 | BO14: ='Background Data'!$X$14*BO13 -> 19.093085 | BP14: ='Background Data'!$X$14*BP13 -> 20.902399 | ... BY14: ='Background Data'!$X$14*BY13 -> 34.156942
AJ15: Plug-in hybrid electric | AR15: ='Background Data'!AD78/AR$10 -> 0 | AS15: ='Background Data'!AE78/AS$10 -> 0 | AT15: ='Background Data'!AF78/AT$10 -> 0 | AU15: ='Background Data'!AG78/AU$10 -> 0 | AV15: ='Background Data'!AH78/AV$10 -> 0 | AW15: ='Background Data'!AI78/AW$10 -> 0 | AX15: ='Background Data'!AJ78/AX$10 -> 0 | AY15: ='Background Data'!AK78/AY$10 -> 0 | ... BD15: ='Background Data'!AP78/BD$10 -> 0 | BG15: Distribution (>2003) | BH15: =BH10/SUM($BH$10:$BZ$10) -> 0.018981448 | BI15: =BI10/SUM($BH$10:$BZ$10) -> 0.021263871 | BJ15: =BJ10/SUM($BH$10:$BZ$10) -> 0.025456766 | BK15: =BK10/SUM($BH$10:$BZ$10) -> 0.030077969 | BL15: =BL10/SUM($BH$10:$BZ$10) -> 0.036918193 | BM15: =BM10/SUM($BH$10:$BZ$10) -> 0.037781851 | BN15: =BN10/SUM($BH$10:$BZ$10) -> 0.031591835 | BO15: =BO10/SUM($BH$10:$BZ$10) -> 0.044320571 | ... BZ15: =BZ10/SUM($BH$10:$BZ$10) -> 0.091479376 | CF15: return 5 * -((vintage - 2000) // -5) + 2000 #
AJ16: Multi-purpose vehicles (Light Trucks) | AR16: ='Background Data'!AD80-'Background Data'!AD86 -> 197405 | AS16: ='Background Data'!AE80-'Background Data'!AE86 -> 199443 | AT16: ='Background Data'!AF80-'Background Data'!AF86 -> 215645 | AU16: ='Background Data'!AG80-'Background Data'!AG86 -> 243844 | AV16: ='Background Data'!AH80-'Background Data'!AH86 -> 284143 | AW16: ='Background Data'!AI80-'Background Data'!AI86 -> 318787 | AX16: ='Background Data'!AJ80-'Background Data'!AJ86 -> 345265 | AY16: ='Background Data'!AK80-'Background Data'!AK86 -> 368223 | ... BD16: ='Background Data'!AP80-'Background Data'!AP86 -> 412101 | BG16: 2021 HT fleet (k units) | BH16: ='Background Data'!$X$15*BH15 -> 2.8111144 | BI16: ='Background Data'!$X$15*BI15 -> 3.1491367 | BJ16: ='Background Data'!$X$15*BJ15 -> 3.7700962 | BK16: ='Background Data'!$X$15*BK15 -> 4.454487 | BL16: ='Background Data'!$X$15*BL15 -> 5.4675106 | BM16: ='Background Data'!$X$15*BM15 -> 5.5954166 | BN16: ='Background Data'!$X$15*BN15 -> 4.6786876 | BO16: ='Background Data'!$X$15*BO15 -> 6.5637879 | ... BY16: ='Background Data'!$X$15*BY15 -> 11.742415
AJ17: Gasoline | AR17: ='Background Data'!AD81/AR$16 -> 0.97816165 | AS17: ='Background Data'!AE81/AS$16 -> 0.97100926 | AT17: ='Background Data'!AF81/AT$16 -> 0.96371351 | AU17: ='Background Data'!AG81/AU$16 -> 0.96030249 | AV17: ='Background Data'!AH81/AV$16 -> 0.96466568 | AW17: ='Background Data'!AI81/AW$16 -> 0.97383206 | AX17: ='Background Data'!AJ81/AX$16 -> 0.97924493 | AY17: ='Background Data'!AK81/AY$16 -> 0.97193548 | ... BD17: ='Background Data'!AP81/BD$16 -> 0.79800583 | BG17: Motorcycle registrations | BJ17: 9068 | BK17: 10820 | BL17: 11655 | BM17: 12072 | BN17: 11711 | BO17: 6270 | BP17: 6679 | BQ17: 7536 | BR17: 8190 | BS17: 8307 | BT17: 8226 | BU17: 8041 | BV17: 8278 | BW17: 8807 | BX17: 8442 | BY17: 6964 | BZ17: 6758 | CF17: vintage
AJ18: Diesel | AR18: ='Background Data'!AD82/AR$16 -> 0.017314658 | AS18: ='Background Data'!AE82/AS$16 -> 0.024473158 | AT18: ='Background Data'!AF82/AT$16 -> 0.032799277 | AU18: ='Background Data'!AG82/AU$16 -> 0.035797477 | AV18: ='Background Data'!AH82/AV$16 -> 0.031610844 | AW18: ='Background Data'!AI82/AW$16 -> 0.013755266 | AX18: ='Background Data'!AJ82/AX$16 -> 0.0059027124 | AY18: ='Background Data'!AK82/AY$16 -> 0.0074357115 | ... BD18: ='Background Data'!AP82/BD$16 -> 0.0044042601 | BG18: Distribution (>2005) | BJ18: =BJ17/SUM($BJ$17:$BZ$17) -> 0.061343219 | BK18: =BK17/SUM($BJ$17:$BZ$17) -> 0.073195151 | BL18: =BL17/SUM($BJ$17:$BZ$17) -> 0.07884376 | BM18: =BM17/SUM($BJ$17:$BZ$17) -> 0.081664682 | BN18: =BN17/SUM($BJ$17:$BZ$17) -> 0.079222589 | BO18: =BO17/SUM($BJ$17:$BZ$17) -> 0.042415305 | BP18: =BP17/SUM($BJ$17:$BZ$17) -> 0.045182108 | BQ18: =BQ17/SUM($BJ$17:$BZ$17) -> 0.050979543 | ... BZ18: =BZ17/SUM($BJ$17:$BZ$17) -> 0.045716528 | CF18: 2003
AJ19: Battery electric | AR19: ='Background Data'!AD83/AR$16 -> 0 | AS19: ='Background Data'!AE83/AS$16 -> 0 | AT19: ='Background Data'!AF83/AT$16 -> 0 | AU19: ='Background Data'!AG83/AU$16 -> 6.1514739e-05 | AV19: ='Background Data'!AH83/AV$16 -> 0.00020764193 | AW19: ='Background Data'!AI83/AW$16 -> 0.0016970579 | AX19: ='Background Data'!AJ83/AX$16 -> 0.0029861121 | AY19: ='Background Data'!AK83/AY$16 -> 0.0024523183 | ... BD19: ='Background Data'!AP83/BD$16 -> 0.062666676 | BG19: 2021 fleet (k units) | BJ19: ='Background Data'!$X$16*BJ18 -> 14.9675 | BK19: ='Background Data'!$X$16*BK18 -> 17.859324 | BL19: ='Background Data'!$X$16*BL18 -> 19.237562 | BM19: ='Background Data'!$X$16*BM18 -> 19.925856 | BN19: ='Background Data'!$X$16*BN18 -> 19.329995 | BO19: ='Background Data'!$X$16*BO18 -> 10.349165 | BP19: ='Background Data'!$X$16*BP18 -> 11.024254 | BQ19: ='Background Data'!$X$16*BQ18 -> 12.438805 | ... BY19: ='Background Data'!$X$16*BY18 -> 11.49467 | CF19: 2004
AJ20: Hybrid electric | AR20: ='Background Data'!AD84/AR$16 -> 0.0045236949 | AS20: ='Background Data'!AE84/AS$16 -> 0.0045175815 | AT20: ='Background Data'!AF84/AT$16 -> 0.0034872128 | AU20: ='Background Data'!AG84/AU$16 -> 0.0037852069 | AV20: ='Background Data'!AH84/AV$16 -> 0.0031638999 | AW20: ='Background Data'!AI84/AW$16 -> 0.0091534473 | AX20: ='Background Data'!AJ84/AX$16 -> 0.01060345 | AY20: ='Background Data'!AK84/AY$16 -> 0.012332201 | ... BD20: ='Background Data'!AP84/BD$16 -> 0.11053601 | BG20: Bus registrations | BN20: 1234 | BO20: 1794 | BP20: 1693 | BQ20: 2090 | BR20: 2352 | BS20: 1971 | BT20: 1816 | BU20: 2327 | BV20: 2802 | BW20: 2500 | BX20: 2995 | BY20: 1830 | BZ20: 1304 | CF20: 2005
AJ21: Plug-in hybrid electric | AR21: ='Background Data'!AD85/AR$16 -> 0 | AS21: ='Background Data'!AE85/AS$16 -> 0 | AT21: ='Background Data'!AF85/AT$16 -> 0 | AU21: ='Background Data'!AG85/AU$16 -> 5.3312774e-05 | AV21: ='Background Data'!AH85/AV$16 -> 0.00035193547 | AW21: ='Background Data'!AI85/AW$16 -> 0.0015621716 | AX21: ='Background Data'!AJ85/AX$16 -> 0.0012627981 | AY21: ='Background Data'!AK85/AY$16 -> 0.0058442846 | ... BD21: ='Background Data'!AP85/BD$16 -> 0.024387225 | BG21: Distribution (>2009) | BN21: =BN20/SUM($BN$20:$BZ$20) -> 0.046203385 | BO21: =BO20/SUM($BN$20:$BZ$20) -> 0.067170885 | BP21: =BP20/SUM($BN$20:$BZ$20) -> 0.063389247 | BQ21: =BQ20/SUM($BN$20:$BZ$20) -> 0.078253707 | BR21: =BR20/SUM($BN$20:$BZ$20) -> 0.088063502 | BS21: =BS20/SUM($BN$20:$BZ$20) -> 0.073798113 | BT21: =BT20/SUM($BN$20:$BZ$20) -> 0.067994608 | BU21: =BU20/SUM($BN$20:$BZ$20) -> 0.087127452 | ... BZ21: =BZ20/SUM($BN$20:$BZ$20) -> 0.048824322 | CF21: 2006
AJ22: Vans (Light Trucks) | AR22: ='Background Data'!AD87-'Background Data'!AD93 -> 54348 | AS22: ='Background Data'!AE87-'Background Data'!AE93 -> 51561 | AT22: ='Background Data'!AF87-'Background Data'!AF93 -> 51829 | AU22: ='Background Data'!AG87-'Background Data'!AG93 -> 55717 | AV22: ='Background Data'!AH87-'Background Data'!AH93 -> 58619 | AW22: ='Background Data'!AI87-'Background Data'!AI93 -> 60304 | AX22: ='Background Data'!AJ87-'Background Data'!AJ93 -> 58851 | AY22: ='Background Data'!AK87-'Background Data'!AK93 -> 54428 | ... BD22: ='Background Data'!AP87-'Background Data'!AP93 -> 26728 | BG22: 2021 BS fleet (k units) | BN22: ='Background Data'!$X17*BN$21 -> 0.58336394 | BO22: ='Background Data'!$X17*BO$21 -> 0.8480996 | BP22: ='Background Data'!$X17*BP$21 -> 0.80035263 | BQ22: ='Background Data'!$X17*BQ$21 -> 0.9880313 | BR22: ='Background Data'!$X17*BR$21 -> 1.1118898 | BS22: ='Background Data'!$X17*BS$21 -> 0.93177497 | BT22: ='Background Data'!$X17*BT$21 -> 0.85849993 | BU22: ='Background Data'!$X17*BU$21 -> 1.1000712 | ... BY22: ='Background Data'!$X17*BY$21 -> 0.86511832 | CF22: 2007
AJ23: Gasoline | AR23: ='Background Data'!AD88/AR$22 -> 0.97468168 | AS23: ='Background Data'!AE88/AS$22 -> 0.97511685 | AT23: ='Background Data'!AF88/AT$22 -> 0.9713095 | AU23: ='Background Data'!AG88/AU$22 -> 0.96772978 | AV23: ='Background Data'!AH88/AV$22 -> 0.95791467 | AW23: ='Background Data'!AI88/AW$22 -> 0.95501128 | AX23: ='Background Data'!AJ88/AX$22 -> 0.95133473 | AY23: ='Background Data'!AK88/AY$22 -> 0.93766076 | ... BD23: ='Background Data'!AP88/BD$22 -> 0.79190362 | BG23: 2021 BT fleet (k units) | BN23: ='Background Data'!$X18*BN$21 -> 0.30508095 | BO23: ='Background Data'!$X18*BO$21 -> 0.44352935 | BP23: ='Background Data'!$X18*BP$21 -> 0.4185592 | BQ23: ='Background Data'!$X18*BQ$21 -> 0.51670923 | BR23: ='Background Data'!$X18*BR$21 -> 0.5814833 | BS23: ='Background Data'!$X18*BS$21 -> 0.48728894 | BT23: ='Background Data'!$X18*BT$21 -> 0.4489684 | BU23: ='Background Data'!$X18*BU$21 -> 0.57530257 | ... BY23: ='Background Data'!$X18*BY$21 -> 0.45242961 | CF23: 2008
AJ24: Diesel | AR24: ='Background Data'!AD89/AR$22 -> 0.02504232 | AS24: ='Background Data'!AE89/AS$22 -> 0.024669809 | AT24: ='Background Data'!AF89/AT$22 -> 0.028690501 | AU24: ='Background Data'!AG89/AU$22 -> 0.032270223 | AV24: ='Background Data'!AH89/AV$22 -> 0.042085331 | AW24: ='Background Data'!AI89/AW$22 -> 0.044972141 | AX24: ='Background Data'!AJ89/AX$22 -> 0.039795416 | AY24: ='Background Data'!AK89/AY$22 -> 0.046262953 | ... BD24: ='Background Data'!AP89/BD$22 -> 0.089419336 | BG24: 2021 BIC fleet (k units) | BN24: ='Background Data'!$X19*BN$21 -> 0.04749708 | BO24: ='Background Data'!$X19*BO$21 -> 0.06905167 | BP24: ='Background Data'!$X19*BP$21 -> 0.065164146 | BQ24: ='Background Data'!$X19*BQ$21 -> 0.080444811 | BR24: ='Background Data'!$X19*BR$21 -> 0.09052928 | BS24: ='Background Data'!$X19*BS$21 -> 0.07586446 | BT24: ='Background Data'!$X19*BT$21 -> 0.069898457 | BU24: ='Background Data'!$X19*BU$21 -> 0.089567021 | ... BY24: ='Background Data'!$X19*BY$21 -> 0.070437322 | CF24: 2009
AJ25: Battery electric | AR25: ='Background Data'!AD90/AR$22 -> 0.00027599912 | AS25: ='Background Data'!AE90/AS$22 -> 0.00021333954 | AT25: ='Background Data'!AF90/AT$22 -> 0 | AU25: ='Background Data'!AG90/AU$22 -> 0 | AV25: ='Background Data'!AH90/AV$22 -> 0 | AW25: ='Background Data'!AI90/AW$22 -> 0 | AX25: ='Background Data'!AJ90/AX$22 -> 0 | AY25: ='Background Data'!AK90/AY$22 -> 0 | ... BD25: ='Background Data'!AP90/BD$22 -> 0.018968872 | CF25: 2010
AJ26: Hybrid electric | AR26: ='Background Data'!AD91/AR$22 -> 0 | AS26: ='Background Data'!AE91/AS$22 -> 0 | AT26: ='Background Data'!AF91/AT$22 -> 0 | AU26: ='Background Data'!AG91/AU$22 -> 0 | AV26: ='Background Data'!AH91/AV$22 -> 0 | AW26: ='Background Data'!AI91/AW$22 -> 0 | AX26: ='Background Data'!AJ91/AX$22 -> 0 | AY26: ='Background Data'!AK91/AY$22 -> 0 | ... BD26: ='Background Data'!AP91/BD$22 -> 0.076511523 | BG26: Fleet stock and flow estimation (in demand units) | CF26: 2011
AJ27: Plug-in hybrid electric | AR27: ='Background Data'!AD92/AR$22 -> 0 | AS27: ='Background Data'!AE92/AS$22 -> 0 | AT27: ='Background Data'!AF92/AT$22 -> 0 | AU27: ='Background Data'!AG92/AU$22 -> 0 | AV27: ='Background Data'!AH92/AV$22 -> 0 | AW27: ='Background Data'!AI92/AW$22 -> 1.6582648e-05 | AX27: ='Background Data'!AJ92/AX$22 -> 0.0088698578 | AY27: ='Background Data'!AK92/AY$22 -> 0.016076284 | ... BD27: ='Background Data'!AP92/BD$22 -> 0.023196648 | BG27: Mode | BH27: 2000 | BI27: 2001 | BJ27: 2002 | BK27: 2003 | BL27: 2004 | BM27: 2005 | BN27: 2006 | BO27: 2007 | BP27: 2008 | BQ27: 2009 | BR27: 2010 | BS27: 2011 | BT27: 2012 | BU27: 2013 | BV27: 2014 | BW27: 2015 | BX27: 2016 | BY27: 2017 | BZ27: 2018 | CA27: 2019 | CB27: 2020 | CC27: % of 2020 demand | CF27: 2012
AJ28: Medium Trucks | AK28: (StatCan, 2023) Table: 23-10-0308-01 | AX28: ='Background Data'!AR74 -> 122905 | AY28: ='Background Data'!AS74 -> 125671 | AZ28: ='Background Data'!AT74 -> 128102 | BA28: ='Background Data'!AU74 -> 138081 | BB28: ='Background Data'!AV74 -> 152693 | BC28: ='Background Data'!AW74 -> 148436 | BD28: ='Background Data'!AX74 -> 147657 | BG28: Passenger airplane | CF28: 2013
AJ29: Gasoline | AL29: =1-AL30 -> 0.4 | AM29: =1-AM30 -> 0.4 | AN29: =1-AN30 -> 0.4 | AO29: =1-AO30 -> 0.4 | AP29: =1-AP30 -> 0.4 | AQ29: =1-AQ30 -> 0.4 | AR29: =1-AR30 -> 0.4 | AS29: =1-AS30 -> 0.4 | ... AW29: =1-AW30 -> 0.4 | AX29: ='Background Data'!AR75/AX$28 -> 0.36206013 | AY29: ='Background Data'!AS75/AY$28 -> 0.3726715 | AZ29: ='Background Data'!AT75/AZ$28 -> 0.38132113 | BA29: ='Background Data'!AU75/BA$28 -> 0.38728717 | BB29: ='Background Data'!AV75/BB$28 -> 0.38496198 | BC29: ='Background Data'!AW75/BC$28 -> 0.39681748 | BD29: ='Background Data'!AX75/BD$28 -> 0.40317086 | BG29: Estimated demand | BH29: ='Background Data'!C86/'Background Data'!C133 -> 34.360329 | BI29: ='Background Data'!D86/'Background Data'!D133 -> 31.904682 | BJ29: ='Background Data'!E86/'Background Data'!E133 -> 22.604161 | BK29: ='Background Data'!F86/'Background Data'!F133 -> 24.092497 | BL29: ='Background Data'!G86/'Background Data'!G133 -> 31.49742 | BM29: ='Background Data'!H86/'Background Data'!H133 -> 42.578942 | BN29: ='Background Data'!I86/'Background Data'!I133 -> 32.525633 | BO29: ='Background Data'!J86/'Background Data'!J133 -> 36.788464 | ... CB29: ='Background Data'!W86/'Background Data'!W133 -> 20.470676 | CF29: 2014
AJ30: Diesel | AL30: 0.6 | AM30: 0.6 | AN30: 0.6 | AO30: 0.6 | AP30: 0.6 | AQ30: 0.6 | AR30: 0.6 | AS30: 0.6 | AT30: 0.6 | AU30: 0.6 | AV30: 0.6 | AW30: 0.6 | AX30: ='Background Data'!AR76/AX$28 -> 0.63789919 | AY30: ='Background Data'!AS76/AY$28 -> 0.62729667 | AZ30: ='Background Data'!AT76/AZ$28 -> 0.61864764 | BA30: ='Background Data'!AU76/BA$28 -> 0.61266213 | BB30: ='Background Data'!AV76/BB$28 -> 0.61497253 | BC30: ='Background Data'!AW76/BC$28 -> 0.60310841 | BD30: ='Background Data'!AX76/BD$28 -> 0.59662596 | BG30: Linear retirement | BH30: =BH29*'Background Data'!$BD$31 -> 1.4316804 | BI30: =BI29*'Background Data'!$BD$31 -> 1.3293617 | BJ30: =BJ29*'Background Data'!$BD$31 -> 0.94184003 | BK30: =BK29*'Background Data'!$BD$31 -> 1.003854 | BL30: =BL29*'Background Data'!$BD$31 -> 1.3123925 | BM30: =BM29*'Background Data'!$BD$31 -> 1.7741226 | BN30: =BN29*'Background Data'!$BD$31 -> 1.3552347 | BO30: =BO29*'Background Data'!$BD$31 -> 1.5328527 | ... CB30: =CB29*'Background Data'!$BD$31 -> 0.85294483 | CF30: 2015
AJ31: Light Passenger Trucks | AK31: (StatCan, 2023) Table: 20-10-0021-01 | AR31: =AR10+AR16+AR22 -> 329779 | AS31: =AS10+AS16+AS22 -> 317690 | AT31: =AT10+AT16+AT22 -> 347875 | AU31: =AU10+AU16+AU22 -> 386329 | AV31: =AV10+AV16+AV22 -> 446940 | AW31: =AW10+AW16+AW22 -> 505914 | AX31: =AX10+AX16+AX22 -> 548179 | AY31: =AY10+AY16+AY22 -> 558012 | ... BD31: =BD10+BD16+BD22 -> 566481 | BG31: Est. new stock | BI31: =BI29-(BH29-BH30) -> -1.0239663 | BJ31: =BJ29-(BI29-BI30) -> -7.9711595 | BK31: =BK29-(BJ29-BJ30) -> 2.4301766 | BL31: =BL29-(BK29-BK30) -> 8.4087768 | BM31: =BM29-(BL29-BL30) -> 12.393915 | BN31: =BN29-(BM29-BM30) -> -8.2791868 | BO31: =BO29-(BN29-BN30) -> 5.618066 | BP31: =BP29-(BO29-BO30) -> 8.9683463 | ... CB31: =CB29-(CA29-CA30) -> -47.177502 | CC31: =SUMIF(BI31:CB31, ">0", BI31:CB31)/CA29 -> 1.271064 | CF31: 2016
AJ32: Gasoline | AL32: 0.95 | AM32: 0.95 | AN32: 0.95 | AO32: 0.95 | AP32: 0.95 | AQ32: 0.95 | AR32: =('Background Data'!AD74+'Background Data'!AD81+'Background Data'!AD88)/(AR$10+AR$16+AR$22) -> 0.96637142 | AS32: =('Background Data'!AE74+'Background Data'!AE81+'Background Data'!AE88)/(AS$10+AS$16+AS$22) -> 0.96194089 | AT32: =('Background Data'!AF74+'Background Data'!AF81+'Background Data'!AF88)/(AT$10+AT$16+AT$22) -> 0.95799641 | AU32: =('Background Data'!AG74+'Background Data'!AG81+'Background Data'!AG88)/(AU$10+AU$16+AU$22) -> 0.94820736 | AV32: =('Background Data'!AH74+'Background Data'!AH81+'Background Data'!AH88)/(AV$10+AV$16+AV$22) -> 0.94716741 | AW32: =('Background Data'!AI74+'Background Data'!AI81+'Background Data'!AI88)/(AW$10+AW$16+AW$22) -> 0.95022672 | AX32: =('Background Data'!AJ74+'Background Data'!AJ81+'Background Data'!AJ88)/(AX$10+AX$16+AX$22) -> 0.958457 | AY32: =('Background Data'!AK74+'Background Data'!AK81+'Background Data'!AK88)/(AY$10+AY$16+AY$22) -> 0.9478022 | ... BD32: =('Background Data'!AP74+'Background Data'!AP81+'Background Data'!AP88)/(BD$10+BD$16+BD$22) -> 0.80020866 | BE32: =1 - SUM(BD32:BD33)/SUM(AZ32:AZ33) -> 0.14681698 | BG32: Freight airplane | CF32: 2017
AJ33: Diesel | AL33: 0.03 | AM33: 0.03 | AN33: 0.03 | AO33: 0.03 | AP33: 0.03 | AQ33: 0.03 | AR33: =('Background Data'!AD75+'Background Data'!AD82+'Background Data'!AD89)/(AR$10+AR$16+AR$22) -> 0.030672056 | AS33: =('Background Data'!AE75+'Background Data'!AE82+'Background Data'!AE89)/(AS$10+AS$16+AS$22) -> 0.035002676 | AT33: =('Background Data'!AF75+'Background Data'!AF82+'Background Data'!AF89)/(AT$10+AT$16+AT$22) -> 0.039816026 | AU33: =('Background Data'!AG75+'Background Data'!AG82+'Background Data'!AG89)/(AU$10+AU$16+AU$22) -> 0.049328422 | AV33: =('Background Data'!AH75+'Background Data'!AH82+'Background Data'!AH89)/(AV$10+AV$16+AV$22) -> 0.050465387 | AW33: =('Background Data'!AI75+'Background Data'!AI82+'Background Data'!AI89)/(AW$10+AW$16+AW$22) -> 0.041949818 | AX33: =('Background Data'!AJ75+'Background Data'!AJ82+'Background Data'!AJ89)/(AX$10+AX$16+AX$22) -> 0.031236147 | AY33: =('Background Data'!AK75+'Background Data'!AK82+'Background Data'!AK89)/(AY$10+AY$16+AY$22) -> 0.037017125 | ... BD33: =('Background Data'!AP75+'Background Data'!AP82+'Background Data'!AP89)/(BD$10+BD$16+BD$22) -> 0.03939938 | BG33: Estimated demand | BH33: ='Background Data'!C87/'Background Data'!C134 -> 0.71092627 | BI33: ='Background Data'!D87/'Background Data'!D134 -> 0.62047248 | BJ33: ='Background Data'!E87/'Background Data'!E134 -> 0.45496306 | BK33: ='Background Data'!F87/'Background Data'!F134 -> 0.46098915 | BL33: ='Background Data'!G87/'Background Data'!G134 -> 0.57398482 | BM33: ='Background Data'!H87/'Background Data'!H134 -> 0.81283196 | BN33: ='Background Data'!I87/'Background Data'!I134 -> 0.55785607 | BO33: ='Background Data'!J87/'Background Data'!J134 -> 0.43074539 | ... CB33: ='Background Data'!W87/'Background Data'!W134 -> 0.77473367 | CF33: 2018
AJ34: Battery electric | AL34: 0 | AM34: 0 | AN34: 0 | AO34: 0 | AP34: 0 | AQ34: 0 | AR34: =('Background Data'!AD83+'Background Data'!AD90+'Background Data'!AD76)/(AR$10+AR$16+AR$22) -> 4.5485007e-05 | AS34: =('Background Data'!AE83+'Background Data'!AE90+'Background Data'!AE76)/(AS$10+AS$16+AS$22) -> 3.4624949e-05 | AT34: =('Background Data'!AF83+'Background Data'!AF90+'Background Data'!AF76)/(AT$10+AT$16+AT$22) -> 0 | AU34: =('Background Data'!AG83+'Background Data'!AG90+'Background Data'!AG76)/(AU$10+AU$16+AU$22) -> 3.882701e-05 | AV34: =('Background Data'!AH83+'Background Data'!AH90+'Background Data'!AH76)/(AV$10+AV$16+AV$22) -> 0.00013200877 | AW34: =('Background Data'!AI83+'Background Data'!AI90+'Background Data'!AI76)/(AW$10+AW$16+AW$22) -> 0.0010693517 | AX34: =('Background Data'!AJ83+'Background Data'!AJ90+'Background Data'!AJ76)/(AX$10+AX$16+AX$22) -> 0.0018807725 | AY34: =('Background Data'!AK83+'Background Data'!AK90+'Background Data'!AK76)/(AY$10+AY$16+AY$22) -> 0.0016182448 | ... BD34: =('Background Data'!AP83+'Background Data'!AP90+'Background Data'!AP76)/(BD$10+BD$16+BD$22) -> 0.049676865 | BG34: Linear retirement | BH34: =BH33*'Background Data'!$BD$31 -> 0.029621928 | BI34: =BI33*'Background Data'!$BD$31 -> 0.02585302 | BJ34: =BJ33*'Background Data'!$BD$31 -> 0.018956794 | BK34: =BK33*'Background Data'!$BD$31 -> 0.019207881 | BL34: =BL33*'Background Data'!$BD$31 -> 0.023916034 | BM34: =BM33*'Background Data'!$BD$31 -> 0.033867998 | BN34: =BN33*'Background Data'!$BD$31 -> 0.023244003 | BO34: =BO33*'Background Data'!$BD$31 -> 0.017947725 | ... CB34: =CB33*'Background Data'!$BD$31 -> 0.03228057 | CF34: 2019
AJ35: Hybrid electric | AL35: 0 | AM35: 0 | AN35: 0 | AO35: 0 | AP35: 0 | AQ35: 0 | AR35: =('Background Data'!AD77+'Background Data'!AD84+'Background Data'!AD91)/(AR$10+AR$16+AR$22) -> 0.0029110404 | AS35: =('Background Data'!AE77+'Background Data'!AE84+'Background Data'!AE91)/(AS$10+AS$16+AS$22) -> 0.0030218137 | AT35: =('Background Data'!AF77+'Background Data'!AF84+'Background Data'!AF91)/(AT$10+AT$16+AT$22) -> 0.0021875674 | AU35: =('Background Data'!AG77+'Background Data'!AG84+'Background Data'!AG91)/(AU$10+AU$16+AU$22) -> 0.0023917438 | AV35: =('Background Data'!AH77+'Background Data'!AH84+'Background Data'!AH91)/(AV$10+AV$16+AV$22) -> 0.0020114557 | AW35: =('Background Data'!AI77+'Background Data'!AI84+'Background Data'!AI91)/(AW$10+AW$16+AW$22) -> 0.0057677787 | AX35: =('Background Data'!AJ77+'Background Data'!AJ84+'Background Data'!AJ91)/(AX$10+AX$16+AX$22) -> 0.0066784755 | AY35: =('Background Data'!AK77+'Background Data'!AK84+'Background Data'!AK91)/(AY$10+AY$16+AY$22) -> 0.0081378178 | ... BD35: =('Background Data'!AP77+'Background Data'!AP84+'Background Data'!AP91)/(BD$10+BD$16+BD$22) -> 0.091879516 | BE35: =BD35/AZ35 - 1 -> 7.0303894 | BG35: Est. new stock | BI35: =BI33-(BH33-BH34) -> -0.060831864 | BJ35: =BJ33-(BI33-BI34) -> -0.1396564 | BK35: =BK33-(BJ33-BJ34) -> 0.024982882 | BL35: =BL33-(BK33-BK34) -> 0.13220355 | BM35: =BM33-(BL33-BL34) -> 0.26276318 | BN35: =BN33-(BM33-BM34) -> -0.2211079 | BO35: =BO33-(BN33-BN34) -> -0.10386667 | BP35: =BP33-(BO33-BO34) -> 0.069226305 | ... CB35: =CB33-(CA33-CA34) -> -0.14238774 | CC35: =SUMIF(BI35:CB35, ">0", BI35:CB35)/CA33 -> 1.3737558 | CF35: 2020
AJ36: Plug-in hybrid electric | AL36: 0 | AM36: 0 | AN36: 0 | AO36: 0 | AP36: 0 | AQ36: 0 | AR36: =('Background Data'!AD85+'Background Data'!AD92)/(AR$10+AR$16+AR$22) -> 0 | AS36: =('Background Data'!AE85+'Background Data'!AE92)/(AS$10+AS$16+AS$22) -> 0 | AT36: =('Background Data'!AF85+'Background Data'!AF92)/(AT$10+AT$16+AT$22) -> 0 | AU36: =('Background Data'!AG85+'Background Data'!AG92)/(AU$10+AU$16+AU$22) -> 3.3650075e-05 | AV36: =('Background Data'!AH85+'Background Data'!AH92)/(AV$10+AV$16+AV$22) -> 0.00022374368 | AW36: =('Background Data'!AI85+'Background Data'!AI92)/(AW$10+AW$16+AW$22) -> 0.00098633365 | AX36: =('Background Data'!AJ85+'Background Data'!AJ92)/(AX$10+AX$16+AX$22) -> 0.0017476043 | AY36: =('Background Data'!AK85+'Background Data'!AK92)/(AY$10+AY$16+AY$22) -> 0.0054246145 | ... BD36: =('Background Data'!AP85+'Background Data'!AP92)/(BD$10+BD$16+BD$22) -> 0.018835583 | BG36: Passenger rail | CF36: 2021
AJ37: Light Freight Trucks | AR37: =AR10+AR22 -> 132374 | AS37: =AS10+AS22 -> 118247 | AT37: =AT10+AT22 -> 132230 | AU37: =AU10+AU22 -> 142485 | AV37: =AV10+AV22 -> 162797 | AW37: =AW10+AW22 -> 187127 | AX37: =AX10+AX22 -> 202914 | AY37: =AY10+AY22 -> 189789 | ... BD37: =BD10+BD22 -> 154380 | BG37: Estimated demand | BH37: ='Background Data'!C88/'Background Data'!C135 -> 0.39191099 | BI37: ='Background Data'!D88/'Background Data'!D135 -> 0.37543435 | BJ37: ='Background Data'!E88/'Background Data'!E135 -> 0.39191487 | BK37: ='Background Data'!F88/'Background Data'!F135 -> 0.30574408 | BL37: ='Background Data'!G88/'Background Data'!G135 -> 0.33238694 | BM37: ='Background Data'!H88/'Background Data'!H135 -> 0.34874055 | BN37: ='Background Data'!I88/'Background Data'!I135 -> 0.30994271 | BO37: ='Background Data'!J88/'Background Data'!J135 -> 0.30205213 | ... CB37: ='Background Data'!W88/'Background Data'!W135 -> 0.049202172
AJ38: Gasoline | AL38: 0.95 | AM38: 0.95 | AN38: 0.95 | AO38: 0.95 | AP38: 0.95 | AQ38: 0.95 | AR38: =('Background Data'!AD74+'Background Data'!AD88)/(AR$10+AR$22) -> 0.94878904 | AS38: =('Background Data'!AE74+'Background Data'!AE88)/(AS$10+AS$22) -> 0.94664558 | AT38: =('Background Data'!AF74+'Background Data'!AF88)/(AT$10+AT$22) -> 0.94867277 | AU38: =('Background Data'!AG74+'Background Data'!AG88)/(AU$10+AU$22) -> 0.92750816 | AV38: =('Background Data'!AH74+'Background Data'!AH88)/(AV$10+AV$22) -> 0.91662623 | AW38: =('Background Data'!AI74+'Background Data'!AI88)/(AW$10+AW$22) -> 0.91001299 | AX38: =('Background Data'!AJ74+'Background Data'!AJ88)/(AX$10+AX$22) -> 0.92308564 | AY38: =('Background Data'!AK74+'Background Data'!AK88)/(AY$10+AY$22) -> 0.90097951 | ... BD38: =('Background Data'!AP74+'Background Data'!AP88)/(BD$10+BD$22) -> 0.80608887 | BE38: =1 - SUM(BD38:BD39)/SUM(AZ38:AZ39) -> 0.060651129 | BG38: Linear retirement | BH38: =BH37*'Background Data'!$BD$32 -> 0.0130637 | BI38: =BI37*'Background Data'!$BD$32 -> 0.012514478 | BJ38: =BJ37*'Background Data'!$BD$32 -> 0.013063829 | BK38: =BK37*'Background Data'!$BD$32 -> 0.010191469 | BL38: =BL37*'Background Data'!$BD$32 -> 0.011079565 | BM38: =BM37*'Background Data'!$BD$32 -> 0.011624685 | BN38: =BN37*'Background Data'!$BD$32 -> 0.010331424 | BO38: =BO37*'Background Data'!$BD$32 -> 0.010068404 | ... CB38: =CB37*'Background Data'!$BD$32 -> 0.0016400724
AJ39: Diesel | AL39: 0.04 | AM39: 0.04 | AN39: 0.04 | AO39: 0.04 | AP39: 0.04 | AQ39: 0.04 | AR39: =('Background Data'!AD75+'Background Data'!AD89)/(AR$10+AR$22) -> 0.050591506 | AS39: =('Background Data'!AE75+'Background Data'!AE89)/(AS$10+AS$22) -> 0.052762438 | AT39: =('Background Data'!AF75+'Background Data'!AF89)/(AT$10+AT$22) -> 0.05125917 | AU39: =('Background Data'!AG75+'Background Data'!AG89)/(AU$10+AU$22) -> 0.072484823 | AV39: =('Background Data'!AH75+'Background Data'!AH89)/(AV$10+AV$22) -> 0.083373772 | AW39: =('Background Data'!AI75+'Background Data'!AI89)/(AW$10+AW$22) -> 0.08998167 | AX39: =('Background Data'!AJ75+'Background Data'!AJ89)/(AX$10+AX$22) -> 0.074341839 | AY39: =('Background Data'!AK75+'Background Data'!AK89)/(AY$10+AY$22) -> 0.094410108 | ... BD39: =('Background Data'!AP75+'Background Data'!AP89)/(BD$10+BD$22) -> 0.13281513 | BG39: Est. new stock | BI39: =BI37-(BH37-BH38) -> -0.0034129392 | BJ39: =BJ37-(BI37-BI38) -> 0.028995001 | BK39: =BK37-(BJ37-BJ38) -> -0.073106965 | BL39: =BL37-(BK37-BK38) -> 0.036834328 | BM39: =BM37-(BL37-BL38) -> 0.027433181 | BN39: =BN37-(BM37-BM38) -> -0.027173159 | BO39: =BO37-(BN37-BN38) -> 0.0024408414 | BP39: =BP37-(BO37-BO38) -> 0.017684556 | ... CB39: =CB37-(CA37-CA38) -> -0.28893492 | CC39: =SUMIF(BI39:CB39, ">0", BI39:CB39)/CA37 -> 0.97616904
AJ40: Battery electric | AL40: 0 | AM40: 0 | AN40: 0 | AO40: 0 | AP40: 0 | AQ40: 0 | AR40: =('Background Data'!AD76+'Background Data'!AD90)/(AR$10+AR$22) -> 0.0001133153 | AS40: =('Background Data'!AE76+'Background Data'!AE90)/(AS$10+AS$22) -> 9.3025616e-05 | AT40: =('Background Data'!AF76+'Background Data'!AF90)/(AT$10+AT$22) -> 0 | AU40: =('Background Data'!AG76+'Background Data'!AG90)/(AU$10+AU$22) -> 0 | AV40: =('Background Data'!AH76+'Background Data'!AH90)/(AV$10+AV$22) -> 0 | AW40: =('Background Data'!AI76+'Background Data'!AI90)/(AW$10+AW$22) -> 0 | AX40: =('Background Data'!AJ76+'Background Data'!AJ90)/(AX$10+AX$22) -> 0 | AY40: =('Background Data'!AK76+'Background Data'!AK90)/(AY$10+AY$22) -> 0 | ... BD40: =('Background Data'!AP76+'Background Data'!AP90)/(BD$10+BD$22) -> 0.015001943 | BG40: Freight rail
...

Sheet Demand
F1: Real 2019 demand | G1: Real 2020 demand | H1: Real 2021 demand | I1: period | Q1: DQI | V1: Model input | X1: Input calculations
A2: commodity | B2: region | C2: reference | D2: data_year | E2: units | I2: 2021 | J2: 2025 | K2: 2030 | L2: 2035 | M2: 2040 | N2: 2045 | O2: 2050 | P2: notes | Q2: Reliability | R2: Representativeness | S2: Temporal | T2: Geographical | U2: Technological
A3: T_D_tkm_hdv_t | B3: ON | C3: Natural Resources Canada. (2023b). Transportation Sector – Ontario. Government of Canada, Natural Resources Canada. https://oee.nrcan.gc.ca/corporate/statistics/neud/dpa/menus/trends/comprehensive/trends_tran_on.cfm | D3: 2023 | E3: btkm | F3: =(1-CFAF!$E$4)*'Background Data'!V26/1000 -> 21.925632 | G3: =(1-CFAF!$E$4)*'Background Data'!W26/1000 -> 19.760978 | H3: =(1-CFAF!$E$4)*'Background Data'!X26/1000 -> 22.165595 | I3: =H3 -> 22.165595 | J3: =$I3*Z$31 -> 24.087223 | K3: =$I3*AA$31 -> 26.811786 | L3: =$I3*AB$31 -> 28.88059 | M3: =$I3*AC$31 -> 30.961234 | N3: =$I3*AD$31 -> 33.011298 | O3: =$I3*AE$31 -> 35.34836 | P3: Based on the findings from Sonia Yet et al. 2022, demand projections are indexed through projected national GDP growth (2019=100), using estimates from the Current Measures Scenario of the Canada's Energy Futures 2023. Initial demand is obtained from 2021 subsector activity, which was impacted by the COVID-19 pandemic. Ontario long-haul/short-haul split from Canadian Freight Analysis Framework 2017 data. | Q3: 2 | R3: 1 | S3: 1 | T3: 1 | U3: 1
A4: T_D_tkm_hdv_t_lh | B4: ON | C4: Natural Resources Canada. (2023b). Transportation Sector – Ontario. Government of Canada, Natural Resources Canada. https://oee.nrcan.gc.ca/corporate/statistics/neud/dpa/menus/trends/comprehensive/trends_tran_on.cfm | D4: 2023 | E4: btkm | F4: =(CFAF!$E$4)*'Background Data'!V26/1000 -> 69.052095 | G4: =(CFAF!$E$4)*'Background Data'!W26/1000 -> 62.234781 | H4: =(CFAF!$E$4)*'Background Data'!X26/1000 -> 69.807827 | I4: =H4 -> 69.807827 | J4: =$I4*Z$31 -> 75.859762 | K4: =$I4*AA$31 -> 84.440437 | L4: =$I4*AB$31 -> 90.955884 | M4: =$I4*AC$31 -> 97.508618 | N4: =$I4*AD$31 -> 103.96504 | O4: =$I4*AE$31 -> 111.32533 | P4: Based on the findings from Sonia Yet et al. 2022, demand projections are indexed through projected national GDP growth (2019=100), using estimates from the Current Measures Scenario of the Canada's Energy Futures 2023. Initial demand is obtained from 2021 subsector activity, which was impacted by the COVID-19 pandemic. Ontario long-haul/short-haul split from Canadian Freight Analysis Framework 2017 data. | Q4: 2 | R4: 1 | S4: 1 | T4: 1 | U4: 1
Y11: CEF 2023 Current Policies Scenario - National Macro Indicators
Y12: Macroindicator | Z12: 2019 | AA12: 2020 | AB12: 2021 | AC12: 2025 | AD12: 2030 | AE12: 2035 | AF12: 2040 | AG12: 2045 | AH12: 2050
Y13: Real Gross Domestic Product ($2012 Millions) | Z13: 2109991 | AA13: 2002923 | AB13: 2103305 | AC13: 2292915 | AD13: 2552272 | AE13: 2749206 | AF13: 2947267 | AG13: 3142417 | AH13: 3364887
Y14: Population (thousands) | Z14: 37601.2 | AA14: 38007.2 | AB14: 38226.5 | AC14: 40909.9 | AD14: 43353.6 | AE14: 45341.8 | AF14: 46928.7 | AG14: 48323.3 | AH14: 49635.1
Y15: Gross Domestic Product Deflator (2012=100) | Z15: 109.6 | AA15: 110.3 | AB15: 119.3 | AC15: 138.4 | AD15: 154.6 | AE15: 170.5 | AF15: 187.6 | AG15: 206.4 | AH15: 227.3
Y16: Consumer Price Index (2002=100) | Z16: 136 | AA16: 137 | AB16: 141.6 | AC16: 164.7 | AD16: 184 | AE16: 203.1 | AF16: 223.8 | AG16: 246.5 | AH16: 271.2
Y17: Canada-US Exchange Rate (C$/US$) | Z17: 1.33 | AA17: 1.34 | AB17: 1.25 | AC17: 1.3 | AD17: 1.27 | AE17: 1.27 | AF17: 1.29 | AG17: 1.3 | AH17: 1.28
Y19: CEF 2023 Current Policies Scenario - GDP and population growth index (2020=100) in Canada
Y20: Indicator | Z20: 2021 | AA20: 2025 | AB20: 2030 | AC20: 2035 | AD20: 2040 | AE20: 2045 | AF20: 2050
Y21: GDP growth | Z21: =AB13/$AA13 -> 1.0501178 | AA21: =AC13/$AA13 -> 1.1447844 | AB21: =AD13/$AA13 -> 1.2742736 | AC21: =AE13/$AA13 -> 1.3725969 | AD21: =AF13/$AA13 -> 1.4714829 | AE21: =AG13/$AA13 -> 1.5689155 | AF21: =AH13/$AA13 -> 1.6799882
Y22: Population growth | Z22: =AB14/$AA14 -> 1.00577 | AA22: =AC14/$AA14 -> 1.0763724 | AB22: =AD14/$AA14 -> 1.1406681 | AC22: =AE14/$AA14 -> 1.1929792 | AD22: =AF14/$AA14 -> 1.2347318 | AE22: =AG14/$AA14 -> 1.2714249 | AF22: =AH14/$AA14 -> 1.3059394
Y24: CEF 2023 Current Policies Scenario - GDP and population growth index (2021=100) in Canada
Y25: Indicator | Z25: 2025 | AA25: 2030 | AB25: 2035 | AC25: 2040 | AD25: 2045 | AE25: 2050
Y26: GDP growth | Z26: =AC13/$AB13 -> 1.0901486 | AA26: =AD13/$AB13 -> 1.2134579 | AB26: =AE13/$AB13 -> 1.3070886 | AC26: =AF13/$AB13 -> 1.4012552 | AD26: =AG13/$AB13 -> 1.4940377 | AE26: =AH13/$AB13 -> 1.5998093
Y27: Population growth | Z27: =AC14/$AB14 -> 1.0701974 | AA27: =AD14/$AB14 -> 1.1341242 | AB27: =AE14/$AB14 -> 1.1861353 | AC27: =AF14/$AB14 -> 1.2276484 | AD27: =AG14/$AB14 -> 1.2641309 | AE27: =AH14/$AB14 -> 1.2984474
Y29: CEF 2023 Current Policies Scenario - GDP and population growth index (2019=100) in Canada
Y30: Indicator | Z30: 2025 | AA30: 2030 | AB30: 2035 | AC30: 2040 | AD30: 2045 | AE30: 2050
Y31: GDP growth | Z31: =AC13/$Z13 -> 1.0866942 | AA31: =AD13/$Z13 -> 1.2096127 | AB31: =AE13/$Z13 -> 1.3029468 | AC31: =AF13/$Z13 -> 1.396815 | AD31: =AG13/$Z13 -> 1.4893035 | AE31: =AH13/$Z13 -> 1.59474
Y32: Population growth | Z32: =AC14/$Z14 -> 1.0879945 | AA32: =AD14/$Z14 -> 1.1529845 | AB32: =AE14/$Z14 -> 1.2058605 | AC32: =AF14/$Z14 -> 1.2480639 | AD32: =AG14/$Z14 -> 1.2851531 | AE32: =AH14/$Z14 -> 1.3200403

Sheet LifetimeTech
A1: region | B1: tech | C1: lifetime | D1: notes | E1: reference | F1: data_year
A2: ON | B2: T_HDV_T_LH_CHRG_LRGBATT | C2: 15 | D2: Lifetime obtained from the Open Energy Outlook 2022. | E2: DeCarolis, J. F., Jaramillo, P., Johnson, J. X., McCollum, D. L., Trutnevyte, E., Daniels, D. C., Akn-Olcum, G., Bergerson, J., Cho, S., Choi, J.-H., Craig, M. T., de Queiroz, A. R., Eshraghi, H., Galik, C. S., Gutowski, T. G., Haapala, K. R., Hodge, B.-M., Hoque, S., Jenkins, J. D., ... Zhou, Y. (2020). Open Energy OutlookLeveraging Open-Source Tools for Collaborative Macro-energy System Modeling Efforts. Joule, 4(12), 25232526. https://doi.org/10.1016/j.joule.2020.11.002 | F2: 2022
